Workbook

Sheet Sheet2
A1: 学号 | B1: 学生姓名 | C1: 语文 | D1: 数学 | E1: 英语 | F1: 政治 | G1: 历史
A2: 240101 | B2: 蔡思腾 | C2: 93 | D2: 90 | E2: 101.5 | F2: 82 | G2: 64
A3: 240102 | B3: 曹智恺 | C3: 61 | D3: 67 | E3: 67 | F3: 46 | G3: 45
A4: 240103 | B4: 陈钧翔 | C4: 78 | D4: 75 | E4: 89 | F4: 79 | G4: 65
A5: 240104 | B5: 陈泽轩 | C5: 88 | D5: 94 | E5: 90 | F5: 63 | G5: 57
A6: 240105 | B6: 皋子昂 | C6: 82 | D6: 72 | E6: 83 | F6: 65 | G6: 47
A7: 240106 | B7: 郭芯彤 | C7: 103 | D7: 83 | E7: 113.5 | F7: 83 | G7: 54
A8: 240107 | B8: 韩欣怡 | C8: 93 | D8: 83 | E8: 91.5 | F8: 84 | G8: 63
A9: 240108 | B9: 李佳桓 | C9: 75 | D9: 63 | E9: 81 | F9: 80 | G9: 64
A10: 240109 | B10: 李俊毅 | C10: 84 | D10: 89 | E10: 80 | F10: 75 | G10: 63
A11: 240110 | B11: 李倩钰 | C11: 97 | D11: 100 | E11: 90 | F11: 69 | G11: 68
A12: 240111 | B12: 李伊晴 | C12: 92 | D12: 74 | E12: 83.5 | F12: 82 | G12: 70
A13: 240112 | B13: 梁羽翘 | C13: 94 | D13: 35 | E13: 87 | F13: 78 | G13: 60
... A54: 240212 | B54: 黄慈静 | C54: 74 | D54: 68 | E54: 64.5 | F54: 65 | G54: 57
A55: 240213 | B55: 黄铭灏 | C55: 未扫，不计排名 | D55: 未扫，不计排名 | E55: 未扫，不计排名 | F55: 未扫，不计排名 | G55: 未扫，不计排名
A56: 240214 | B56: 邝迎峰 | C56: 99 | D56: 88 | E56: 110 | F56: 77 | G56: 78
A57: 240215 | B57: 赖俊轩 | C57: 87 | D57: 70 | E57: 91 | F57: 72 | G57: 53
A58: 240216 | B58: 黎昊轩 | C58: 89 | D58: 89 | E58: 101 | F58: 71 | G58: 48
A59: 240217 | B59: 黎皓哲 | C59: 85 | D59: 93 | E59: 110 | F59: 68 | G59: 62
A60: 240218 | B60: 李济瑜 | C60: 103 | D60: 100 | E60: 105 | F60: 73 | G60: 80
A61: 240219 | B61: 李明轩 | C61: 96 | D61: 83 | E61: 90 | F61: 75 | G61: 58
A62: 240220 | B62: 李千海 | C62: 89 | D62: 50 | E62: 78.5 | F62: 74 | G62: 59
A63: 240221 | B63: 李宇涵 | C63: 83 | D63: 75 | E63: 100 | F63: 56 | G63: 64
A64: 240222 | B64: 梁洛迪 | C64: 91 | D64: 76 | E64: 102.5 | F64: 79 | G64: 64
A65: 240223 | B65: 廖紫媗 | C65: 91 | D65: 94 | E65: 101.5 | F65: 76 | G65: 76
A66: 240224 | B66: 林语童 | C66: 96 | D66: 97 | E66: 101 | F66: 86 | G66: 73
A67: 240225 | B67: 刘益馨 | C67: 83 | D67: 50 | E67: 73 | F67: 49 | G67: 54
... A95: 240311 | B95: 黄家佳 | C95: 65 | D95: 45 | E95: 75.5 | F95: 59 | G95: 48
A96: 240312 | B96: 江岳燊 | C96: 未扫，不计排名 | D96: 未扫，不计排名 | E96: 未扫，不计排名 | F96: 未扫，不计排名 | G96: 未扫，不计排名
A97: 240313 | B97: 邝晟竣 | C97: 72 | D97: 93 | E97: 78.5 | F97: 55 | G97: 65
A98: 240314 | B98: 旷梓辰 | C98: 100 | D98: 66 | E98: 102 | F98: 85 | G98: 62
A99: 240315 | B99: 赖炫均 | C99: 99 | D99: 87 | E99: 104 | F99: 89 | G99: 86
A100: 240316 | B100: 李天予 | C100: 94 | D100: 84 | E100: 101 | F100: 68 | G100: 66
A101: 240317 | B101: 李芷彤 | C101: 85 | D101: 95 | E101: 101.5 | F101: 83 | G101: 74
A102: 240318 | B102: 廖康成 | C102: 84 | D102: 87 | E102: 77 | F102: 72 | G102: 58
A103: 240319 | B103: 龙海悦 | C103: 99 | D103: 65 | E103: 101.5 | F103: 83 | G103: 68
A104: 240320 | B104: 卢泓睿 | C104: 86 | D104: 77 | E104: 101 | F104: 67 | G104: 66
A105: 240321 | B105: 毛佳婧 | C105: 91 | D105: 75 | E105: 70 | F105: 68 | G105: 64
A106: 240322 | B106: 莫芷淇 | C106: 105 | D106: 74 | E106: 108 | F106: 86 | G106: 70
A107: 240323 | B107: 莫子奕 | C107: 105 | D107: 104 | E107: 111.5 | F107: 88 | G107: 83
...

Sheet Sheet1
A1: 学号 | B1: 学生姓名 | C1: 语文 | D1: 数学 | E1: 英语 | F1: 政治 | G1: 历史
A2: 240101 | B2: 蔡思腾 | C2: =VLOOKUP($B2,Sheet3!$B:$G,2,0) -> 93 | D2: =VLOOKUP($B2,Sheet3!$B:$G,3,0) -> 90 | E2: =VLOOKUP($B2,Sheet3!$B:$G,4,0) -> 101.5 | F2: =VLOOKUP($B2,Sheet3!$B:$G,6,0) -> 82 | G2: =VLOOKUP($B2,Sheet3!$B:$G,5,0) -> 64
A3: 240102 | B3: 曹智恺 | C3: =VLOOKUP($B3,Sheet3!$B:$G,2,0) -> 61 | D3: =VLOOKUP($B3,Sheet3!$B:$G,3,0) -> 67 | E3: =VLOOKUP($B3,Sheet3!$B:$G,4,0) -> 67 | F3: =VLOOKUP($B3,Sheet3!$B:$G,6,0) -> 46 | G3: =VLOOKUP($B3,Sheet3!$B:$G,5,0) -> 45
A4: 240103 | B4: 陈钧翔 | C4: =VLOOKUP($B4,Sheet3!$B:$G,2,0) -> 78 | D4: =VLOOKUP($B4,Sheet3!$B:$G,3,0) -> 75 | E4: =VLOOKUP($B4,Sheet3!$B:$G,4,0) -> 89 | F4: =VLOOKUP($B4,Sheet3!$B:$G,6,0) -> 79 | G4: =VLOOKUP($B4,Sheet3!$B:$G,5,0) -> 65
A5: 240104 | B5: 陈泽轩 | C5: =VLOOKUP($B5,Sheet3!$B:$G,2,0) -> 88 | D5: =VLOOKUP($B5,Sheet3!$B:$G,3,0) -> 94 | E5: =VLOOKUP($B5,Sheet3!$B:$G,4,0) -> 90 | F5: =VLOOKUP($B5,Sheet3!$B:$G,6,0) -> 63 | G5: =VLOOKUP($B5,Sheet3!$B:$G,5,0) -> 57
A6: 240105 | B6: 皋子昂 | C6: =VLOOKUP($B6,Sheet3!$B:$G,2,0) -> 82 | D6: =VLOOKUP($B6,Sheet3!$B:$G,3,0) -> 72 | E6: =VLOOKUP($B6,Sheet3!$B:$G,4,0) -> 83 | F6: =VLOOKUP($B6,Sheet3!$B:$G,6,0) -> 65 | G6: =VLOOKUP($B6,Sheet3!$B:$G,5,0) -> 47
A7: 240106 | B7: 郭芯彤 | C7: =VLOOKUP($B7,Sheet3!$B:$G,2,0) -> 103 | D7: =VLOOKUP($B7,Sheet3!$B:$G,3,0) -> 83 | E7: =VLOOKUP($B7,Sheet3!$B:$G,4,0) -> 113.5 | F7: =VLOOKUP($B7,Sheet3!$B:$G,6,0) -> 83 | G7: =VLOOKUP($B7,Sheet3!$B:$G,5,0) -> 54
A8: 240107 | B8: 韩欣怡 | C8: =VLOOKUP($B8,Sheet3!$B:$G,2,0) -> 93 | D8: =VLOOKUP($B8,Sheet3!$B:$G,3,0) -> 83 | E8: =VLOOKUP($B8,Sheet3!$B:$G,4,0) -> 91.5 | F8: =VLOOKUP($B8,Sheet3!$B:$G,6,0) -> 84 | G8: =VLOOKUP($B8,Sheet3!$B:$G,5,0) -> 63
A9: 240108 | B9: 李佳桓 | C9: =VLOOKUP($B9,Sheet3!$B:$G,2,0) -> 75 | D9: =VLOOKUP($B9,Sheet3!$B:$G,3,0) -> 63 | E9: =VLOOKUP($B9,Sheet3!$B:$G,4,0) -> 81 | F9: =VLOOKUP($B9,Sheet3!$B:$G,6,0) -> 80 | G9: =VLOOKUP($B9,Sheet3!$B:$G,5,0) -> 64
A10: 240109 | B10: 李俊毅 | C10: =VLOOKUP($B10,Sheet3!$B:$G,2,0) -> 84 | D10: =VLOOKUP($B10,Sheet3!$B:$G,3,0) -> 89 | E10: =VLOOKUP($B10,Sheet3!$B:$G,4,0) -> 80 | F10: =VLOOKUP($B10,Sheet3!$B:$G,6,0) -> 75 | G10: =VLOOKUP($B10,Sheet3!$B:$G,5,0) -> 63
A11: 240110 | B11: 李倩钰 | C11: =VLOOKUP($B11,Sheet3!$B:$G,2,0) -> 97 | D11: =VLOOKUP($B11,Sheet3!$B:$G,3,0) -> 100 | E11: =VLOOKUP($B11,Sheet3!$B:$G,4,0) -> 90 | F11: =VLOOKUP($B11,Sheet3!$B:$G,6,0) -> 69 | G11: =VLOOKUP($B11,Sheet3!$B:$G,5,0) -> 68
A12: 240111 | B12: 李伊晴 | C12: =VLOOKUP($B12,Sheet3!$B:$G,2,0) -> 92 | D12: =VLOOKUP($B12,Sheet3!$B:$G,3,0) -> 74 | E12: =VLOOKUP($B12,Sheet3!$B:$G,4,0) -> 83.5 | F12: =VLOOKUP($B12,Sheet3!$B:$G,6,0) -> 82 | G12: =VLOOKUP($B12,Sheet3!$B:$G,5,0) -> 70
A13: 240112 | B13: 梁羽翘 | C13: =VLOOKUP($B13,Sheet3!$B:$G,2,0) -> 94 | D13: =VLOOKUP($B13,Sheet3!$B:$G,3,0) -> 35 | E13: =VLOOKUP($B13,Sheet3!$B:$G,4,0) -> 87 | F13: =VLOOKUP($B13,Sheet3!$B:$G,6,0) -> 78 | G13: =VLOOKUP($B13,Sheet3!$B:$G,5,0) -> 60
... A688: 230545 | B688: 冯诗芸 | C688: =VLOOKUP($B688,Sheet3!$B:$G,2,0) -> 56 | D688: =VLOOKUP($B688,Sheet3!$B:$G,3,0) -> 30 | E688: =VLOOKUP($B688,Sheet3!$B:$G,4,0) -> 未扫，不计排名 | F688: =VLOOKUP($B688,Sheet3!$B:$G,6,0) -> 未扫，不计排名 | G688: =VLOOKUP($B688,Sheet3!$B:$G,5,0) -> 62

Sheet Sheet3
A1: 班级 | B1: 姓名 | C1: 语文 | D1: 数学 | E1: 英语 | F1: 历史 | G1: 道德与法治
C2: 得分 | D2: 得分 | E2: 得分 | F2: 得分 | G2: 得分
A3: 七年级10班 | B3: 陈奕良 | C3: 109 | D3: 115 | E3: 116.5 | F3: 87 | G3: 89
A4: 七年级7班 | B4: 林梓妍 | C4: 110 | D4: 115 | E4: 119 | F4: 81 | G4: 90
A5: 七年级7班 | B5: 罗宝雯 | C5: 111 | D5: 112 | E5: 118.5 | F5: 88 | G5: 85
A6: 七年级11班 | B6: 张金烨 | C6: 113 | D6: 112 | E6: 111 | F6: 84 | G6: 90
A7: 七年级9班 | B7: 郑思远 | C7: 106 | D7: 113 | E7: 115 | F7: 85 | G7: 90
A8: 七年级10班 | B8: 胡崇根 | C8: 108 | D8: 112 | E8: 115 | F8: 85 | G8: 88
A9: 七年级12班 | B9: 杨安宁 | C9: 110 | D9: 106 | E9: 117 | F9: 83 | G9: 88
A10: 七年级10班 | B10: 颜宇瀚 | C10: 108 | D10: 104 | E10: 116.5 | F10: 84 | G10: 90
A11: 七年级9班 | B11: 张梓梓 | C11: 108 | D11: 106 | E11: 117 | F11: 85 | G11: 85
A12: 七年级7班 | B12: 严皓鹏 | C12: 111 | D12: 108 | E12: 112 | F12: 83 | G12: 86
A13: 七年级13班 | B13: 林楷桐 | C13: 104 | D13: 110 | E13: 115.5 | F13: 82 | G13: 88
A14: 七年级9班 | B14: 卢子乐 | C14: 110 | D14: 103 | E14: 117 | F14: 82 | G14: 87
... A676: 七年级16班 | B676: 尹浩天 | C676: 32 | D676: 20 | E676: 33 | F676: 33 | G676: 32
A677: 七年级17班 | B677: 冯诗芸 | C677: 56 | D677: 30 | E677: 未扫，不计排名 | F677: 62 | G677: 未扫，不计排名
A678: 七年级6班 | B678: 曹展豪 | C678: 38 | D678: 14 | E678: 33 | F678: 18 | G678: 45
A679: 七年级11班 | B679: 焦浩轩 | C679: 未扫，不计排名 | D679: 未扫，不计排名 | E679: 85.5 | F679: 未扫，不计排名 | G679: 59
A680: 七年级6班 | B680: 蔡琦 | C680: 56 | D680: 46 | E680: 未扫，不计排名 | F680: 41 | G680: 未扫，不计排名
A681: 七年级11班 | B681: 李孝濂 | C681: 未扫，不计排名 | D681: 未扫，不计排名 | E681: 67.5 | F681: 未扫，不计排名 | G681: 63
A682: 七年级15班 | B682: 李邦烨 | C682: 51 | D682: 5 | E682: 未扫，不计排名 | F682: 27 | G682: 未扫，不计排名
A683: 七年级2班 | B683: 黄铭灏 | C683: 未扫，不计排名 | D683: 未扫，不计排名 | E683: 未扫，不计排名 | F683: 未扫，不计排名 | G683: 未扫，不计排名
A684: 七年级9班 | B684: 赵屹骁 | C684: 未扫，不计排名 | D684: 未扫，不计排名 | E684: 未扫，不计排名 | F684: 未扫，不计排名 | G684: 未扫，不计排名
A685: 七年级14班 | B685: 邱子轩 | C685: 未扫，不计排名 | D685: 未扫，不计排名 | E685: 未扫，不计排名 | F685: 未扫，不计排名 | G685: 未扫，不计排名
A686: 七年级14班 | B686: 谭竣为 | C686: 未扫，不计排名 | D686: 未扫，不计排名 | E686: 未扫，不计排名 | F686: 未扫，不计排名 | G686: 未扫，不计排名
A687: 七年级14班 | B687: 于子萱 | C687: 未扫，不计排名 | D687: 未扫，不计排名 | E687: 未扫，不计排名 | F687: 未扫，不计排名 | G687: 未扫，不计排名
A688: 七年级14班 | B688: 甄瀚曦 | C688: 未扫，不计排名 | D688: 未扫，不计排名 | E688: 未扫，不计排名 | F688: 未扫，不计排名 | G688: 未扫，不计排名
A689: 七年级6班 | B689: 蔡景雯 | C689: 未扫，不计排名 | D689: 未扫，不计排名 | E689: 未扫，不计排名 | F689: 未扫，不计排名 | G689: 未扫，不计排名
A690: 七年级6班 | B690: 曾思朗 | C690: 未扫，不计排名 | D690: 未扫，不计排名 | E690: 未扫，不计排名 | F690: 未扫，不计排名 | G690: 未扫，不计排名
A691: 七年级6班 | B691: 邓煜辰 | C691: 未扫，不计排名 | D691: 未扫，不计排名 | E691: 未扫，不计排名 | F691: 未扫，不计排名 | G691: 未扫，不计排名
A692: 七年级16班 | B692: 江笛子 | C692: 未扫，不计排名 | D692: 未扫，不计排名 | E692: 未扫，不计排名 | F692: 未扫，不计排名 | G692: 未扫，不计排名
A693: 七年级13班 | B693: 李浩韫 | C693: 未扫，不计排名 | D693: 未扫，不计排名 | E693: 未扫，不计排名 | F693: 未扫，不计排名 | G693: 未扫，不计排名
A694: 七年级5班 | B694: 吴相泽 | C694: 未扫，不计排名 | D694: 未扫，不计排名 | E694: 未扫，不计排名 | F694: 未扫，不计排名 | G694: 未扫，不计排名
... A698: 七年级14班 | B698: 黄彦宏 | C698: 未扫，不计排名 | D698: 未扫，不计排名 | E698: 未扫，不计排名 | F698: 未扫，不计排名 | G698: 未扫，不计排名
