Workbook

Sheet Sheet3
A1: 学号 | B1: 学生姓名 | C1: 语文 | D1: 数学 | E1: 英语 | F1: 物理 | G1: 政治 | H1: 历史
A2: 230101 | B2: 包为民 | C2: 91 | D2: 95 | E2: 91 | F2: 84 | G2: 66 | H2: 75
A3: 230102 | B3: 曾劲松 | C3: 90 | D3: 77 | E3: 83.5 | F3: 85 | G3: 73 | H3: 75
A4: 230103 | B4: 陈博凯 | C4: 85 | D4: 85 | E4: 66 | F4: 81 | G4: 71 | H4: 53
A5: 230105 | B5: 刁艺翔 | C5: 69 | D5: 63 | E5: 50.5 | F5: 67 | G5: 64 | H5: 55
A6: 230106 | B6: 范文翔 | C6: 57 | D6: 68 | E6: 73 | F6: 46 | G6: 51 | H6: 34
A7: 230108 | B7: 范子沫 | C7: 97 | D7: 91 | E7: 97 | F7: 80 | G7: 76 | H7: 74
A8: 230109 | B8: 冯浚杰 | C8: 91 | D8: 71 | E8: 65.5 | F8: 48 | G8: 59 | H8: 49
A9: 230110 | B9: 黄欢畅 | C9: 73.5 | D9: 86 | E9: 36 | F9: 76 | G9: 56 | H9: 60
A10: 230111 | B10: 黄天佑 | C10: 90 | D10: 96 | E10: 105 | F10: 87 | G10: 77 | H10: 66
A11: 230112 | B11: 姜晨旭 | C11: 61 | D11: 44 | E11: 53 | F11: 53 | G11: 40 | H11: 32
A12: 230114 | B12: 李浩森 | C12: 54 | D12: 19 | E12: 42.5 | F12: 20 | G12: 45 | H12: 33
A13: 230115 | B13: 李鸣冲 | C13: 94 | D13: 76 | E13: 78.5 | F13: 65 | G13: 67 | H13: 68
... A28: 230132 | B28: 吴定涵 | C28: 95 | D28: 82 | E28: 86.5 | F28: 84 | G28: 63 | H28: 77
A29: 230133 | B29: 许耀丹 | C29: 未扫，不计排名 | D29: 未扫，不计排名 | E29: 未扫，不计排名 | F29: 未扫，不计排名 | G29: 未扫，不计排名 | H29: 未扫，不计排名
A30: 230134 | B30: 叶晋衡 | C30: 75 | D30: 59 | E30: 83.5 | F30: 64 | G30: 57 | H30: 58
A31: 230135 | B31: 叶晋熙 | C31: 78.5 | D31: 68 | E31: 56 | F31: 52 | G31: 56 | H31: 50
A32: 230136 | B32: 叶雨晗 | C32: 89 | D32: 93 | E32: 81.5 | F32: 84 | G32: 72 | H32: 65
A33: 230137 | B33: 张苗苗 | C33: 70.5 | D33: 72 | E33: 65 | F33: 55 | G33: 60 | H33: 71
A34: 230138 | B34: 郑光耀 | C34: 95 | D34: 68 | E34: 92.5 | F34: 76 | G34: 74 | H34: 77
A35: 230139 | B35: 钟恩琳 | C35: 75 | D35: 70 | E35: 88.5 | F35: 57 | G35: 59 | H35: 60
A36: 230141 | B36: 钟梓萌 | C36: 95 | D36: 85 | E36: 80 | F36: 82 | G36: 77 | H36: 80
A37: 230142 | B37: 朱浩宇 | C37: 63 | D37: 27 | E37: 35 | F37: 54 | G37: 52 | H37: 54
A38: 230143 | B38: 朱文皓哲 | C38: 83 | D38: 77 | E38: 73.5 | F38: 73 | G38: 54 | H38: 59
A39: 230144 | B39: 诸言 | C39: 88 | D39: 74 | E39: 59 | F39: 75 | G39: 67 | H39: 61
A40: 230146 | B40: 林子健 | C40: 87 | D40: 75 | E40: 63 | F40: 65 | G40: 76 | H40: 77
A41: 230147 | B41: 黄浩燃 | C41: #N/A | D41: #N/A | E41: #N/A | F41: #N/A | G41: #N/A | H41: #N/A
A42: 230202 | B42: 陈峻灏 | C42: 86.5 | D42: 75 | E42: 101.5 | F42: 56 | G42: 55 | H42: 67
A43: 230203 | B43: 陈芷君 | C43: 87 | D43: 78 | E43: 64.5 | F43: 84 | G43: 69 | H43: 60
A44: 230204 | B44: 成紫强 | C44: 80 | D44: 61 | E44: 33 | F44: 76 | G44: 62 | H44: 72
A45: 230205 | B45: 范洛铨 | C45: 56 | D45: 23 | E45: 24 | F45: 45 | G45: 42 | H45: 26
A46: 230206 | B46: 何语筠 | C46: 93 | D46: 59 | E46: 86.5 | F46: 59 | G46: 67 | H46: 86
A47: 230208 | B47: 黄磊 | C47: 93 | D47: 69 | E47: 78 | F47: 62 | G47: 68 | H47: 73
A48: 230209 | B48: 黄文轩 | C48: 77 | D48: 59 | E48: 49.5 | F48: 73 | G48: 57 | H48: 73
A49: 230210 | B49: 黄炫凯 | C49: 89 | D49: 86 | E49: 97 | F49: 84 | G49: 79 | H49: 66
A50: 230211 | B50: 黄梓源 | C50: 72 | D50: 55 | E50: 70 | F50: 67 | G50: 44 | H50: 41
A51: 230212 | B51: 嵇祤宸 | C51: 77 | D51: 17 | E51: 25.5 | F51: 37 | G51: 57 | H51: 48
A52: 230213 | B52: 李百恩 | C52: 91 | D52: 99 | E52: 109.5 | F52: 85 | G52: 75 | H52: 77
A53: 230214 | B53: 李睿杰 | C53: 74.5 | D53: 68 | E53: 59 | F53: 56 | G53: 62 | H53: 71
... A193: 230534 | B193: 许宇畅 | C193: 82 | D193: 81 | E193: 62.5 | F193: 78 | G193: 62 | H193: 70
...

Sheet Sheet1
A1: 学号 | B1: 学生姓名 | C1: 语文 | D1: 数学 | E1: 英语 | F1: 物理 | G1: 政治 | H1: 历史
A2: 230101 | B2: 包为民 | C2: =VLOOKUP($B2,Sheet2!$A:$E,2,0) -> 91 | D2: =VLOOKUP($B2,Sheet2!$A:$E,3,0) -> 95 | E2: =VLOOKUP($B2,Sheet2!$A:$E,4,0) -> 91 | F2: =VLOOKUP($B2,Sheet2!$A:$E,5,0) -> 84 | G2: =VLOOKUP($B2,Sheet2!$A:$G,7,0) -> 66 | H2: =VLOOKUP($B2,Sheet2!$A:$G,6,0) -> 75
A3: 230102 | B3: 曾劲松 | C3: =VLOOKUP($B3,Sheet2!$A:$E,2,0) -> 90 | D3: =VLOOKUP($B3,Sheet2!$A:$E,3,0) -> 77 | E3: =VLOOKUP($B3,Sheet2!$A:$E,4,0) -> 83.5 | F3: =VLOOKUP($B3,Sheet2!$A:$E,5,0) -> 85 | G3: =VLOOKUP($B3,Sheet2!$A:$G,7,0) -> 73 | H3: =VLOOKUP($B3,Sheet2!$A:$G,6,0) -> 75
A4: 230103 | B4: 陈博凯 | C4: =VLOOKUP($B4,Sheet2!$A:$E,2,0) -> 85 | D4: =VLOOKUP($B4,Sheet2!$A:$E,3,0) -> 85 | E4: =VLOOKUP($B4,Sheet2!$A:$E,4,0) -> 66 | F4: =VLOOKUP($B4,Sheet2!$A:$E,5,0) -> 81 | G4: =VLOOKUP($B4,Sheet2!$A:$G,7,0) -> 71 | H4: =VLOOKUP($B4,Sheet2!$A:$G,6,0) -> 53
A5: 230105 | B5: 刁艺翔 | C5: =VLOOKUP($B5,Sheet2!$A:$E,2,0) -> 69 | D5: =VLOOKUP($B5,Sheet2!$A:$E,3,0) -> 63 | E5: =VLOOKUP($B5,Sheet2!$A:$E,4,0) -> 50.5 | F5: =VLOOKUP($B5,Sheet2!$A:$E,5,0) -> 67 | G5: =VLOOKUP($B5,Sheet2!$A:$G,7,0) -> 64 | H5: =VLOOKUP($B5,Sheet2!$A:$G,6,0) -> 55
A6: 230106 | B6: 范文翔 | C6: =VLOOKUP($B6,Sheet2!$A:$E,2,0) -> 57 | D6: =VLOOKUP($B6,Sheet2!$A:$E,3,0) -> 68 | E6: =VLOOKUP($B6,Sheet2!$A:$E,4,0) -> 73 | F6: =VLOOKUP($B6,Sheet2!$A:$E,5,0) -> 46 | G6: =VLOOKUP($B6,Sheet2!$A:$G,7,0) -> 51 | H6: =VLOOKUP($B6,Sheet2!$A:$G,6,0) -> 34
A7: 230108 | B7: 范子沫 | C7: =VLOOKUP($B7,Sheet2!$A:$E,2,0) -> 97 | D7: =VLOOKUP($B7,Sheet2!$A:$E,3,0) -> 91 | E7: =VLOOKUP($B7,Sheet2!$A:$E,4,0) -> 97 | F7: =VLOOKUP($B7,Sheet2!$A:$E,5,0) -> 80 | G7: =VLOOKUP($B7,Sheet2!$A:$G,7,0) -> 76 | H7: =VLOOKUP($B7,Sheet2!$A:$G,6,0) -> 74
A8: 230109 | B8: 冯浚杰 | C8: =VLOOKUP($B8,Sheet2!$A:$E,2,0) -> 91 | D8: =VLOOKUP($B8,Sheet2!$A:$E,3,0) -> 71 | E8: =VLOOKUP($B8,Sheet2!$A:$E,4,0) -> 65.5 | F8: =VLOOKUP($B8,Sheet2!$A:$E,5,0) -> 48 | G8: =VLOOKUP($B8,Sheet2!$A:$G,7,0) -> 59 | H8: =VLOOKUP($B8,Sheet2!$A:$G,6,0) -> 49
A9: 230110 | B9: 黄欢畅 | C9: =VLOOKUP($B9,Sheet2!$A:$E,2,0) -> 73.5 | D9: =VLOOKUP($B9,Sheet2!$A:$E,3,0) -> 86 | E9: =VLOOKUP($B9,Sheet2!$A:$E,4,0) -> 36 | F9: =VLOOKUP($B9,Sheet2!$A:$E,5,0) -> 76 | G9: =VLOOKUP($B9,Sheet2!$A:$G,7,0) -> 56 | H9: =VLOOKUP($B9,Sheet2!$A:$G,6,0) -> 60
A10: 230111 | B10: 黄天佑 | C10: =VLOOKUP($B10,Sheet2!$A:$E,2,0) -> 90 | D10: =VLOOKUP($B10,Sheet2!$A:$E,3,0) -> 96 | E10: =VLOOKUP($B10,Sheet2!$A:$E,4,0) -> 105 | F10: =VLOOKUP($B10,Sheet2!$A:$E,5,0) -> 87 | G10: =VLOOKUP($B10,Sheet2!$A:$G,7,0) -> 77 | H10: =VLOOKUP($B10,Sheet2!$A:$G,6,0) -> 66
A11: 230112 | B11: 姜晨旭 | C11: =VLOOKUP($B11,Sheet2!$A:$E,2,0) -> 61 | D11: =VLOOKUP($B11,Sheet2!$A:$E,3,0) -> 44 | E11: =VLOOKUP($B11,Sheet2!$A:$E,4,0) -> 53 | F11: =VLOOKUP($B11,Sheet2!$A:$E,5,0) -> 53 | G11: =VLOOKUP($B11,Sheet2!$A:$G,7,0) -> 40 | H11: =VLOOKUP($B11,Sheet2!$A:$G,6,0) -> 32
A12: 230114 | B12: 李浩森 | C12: =VLOOKUP($B12,Sheet2!$A:$E,2,0) -> 54 | D12: =VLOOKUP($B12,Sheet2!$A:$E,3,0) -> 19 | E12: =VLOOKUP($B12,Sheet2!$A:$E,4,0) -> 42.5 | F12: =VLOOKUP($B12,Sheet2!$A:$E,5,0) -> 20 | G12: =VLOOKUP($B12,Sheet2!$A:$G,7,0) -> 45 | H12: =VLOOKUP($B12,Sheet2!$A:$G,6,0) -> 33
A13: 230115 | B13: 李鸣冲 | C13: =VLOOKUP($B13,Sheet2!$A:$E,2,0) -> 94 | D13: =VLOOKUP($B13,Sheet2!$A:$E,3,0) -> 76 | E13: =VLOOKUP($B13,Sheet2!$A:$E,4,0) -> 78.5 | F13: =VLOOKUP($B13,Sheet2!$A:$E,5,0) -> 65 | G13: =VLOOKUP($B13,Sheet2!$A:$G,7,0) -> 67 | H13: =VLOOKUP($B13,Sheet2!$A:$G,6,0) -> 68
... A800: 231944 | B800: 周彦彤 | C800: =VLOOKUP($B800,Sheet2!$A:$E,2,0) -> 110 | D800: =VLOOKUP($B800,Sheet2!$A:$E,3,0) -> 102 | E800: =VLOOKUP($B800,Sheet2!$A:$E,4,0) -> 118.5 | F800: =VLOOKUP($B800,Sheet2!$A:$E,5,0) -> 89 | G800: =VLOOKUP($B800,Sheet2!$A:$G,7,0) -> 84 | H800: =VLOOKUP($B800,Sheet2!$A:$G,6,0) -> 85

Sheet Sheet2
A1: 姓名 | B1: 语文 | C1: 数学 | D1: 英语 | E1: 物理 | F1: 历史 | G1: 道德与法治
B2: 得分 | C2: 得分 | D2: 得分 | E2: 得分 | F2: 得分 | G2: 得分
A3: 何思璇 | B3: 114 | C3: 119 | D3: 113.5 | E3: 88 | F3: 90 | G3: 84
A4: 冯梓皓 | B4: 113 | C4: 114 | D4: 118.5 | E4: 89 | F4: 84 | G4: 90
A5: 陈迎菲 | B5: 118 | C5: 109 | D5: 117 | E5: 88 | F5: 88 | G5: 87
A6: 鲁可倾 | B6: 115 | C6: 118 | D6: 115.5 | E6: 88 | F6: 87 | G6: 82
A7: 刘彧恺 | B7: 117 | C7: 116 | D7: 113 | E7: 89 | F7: 86 | G7: 84
A8: 王泓颖 | B8: 117.5 | C8: 114 | D8: 115 | E8: 87 | F8: 85 | G8: 80
A9: 张艺菱 | B9: 102 | C9: 116 | D9: 119 | E9: 85 | F9: 88 | G9: 88
A10: 郭书祎 | B10: 104 | C10: 119 | D10: 114 | E10: 87 | F10: 87 | G10: 85
A11: 吕祉诺 | B11: 113 | C11: 117 | D11: 114 | E11: 89 | F11: 88 | G11: 75
A12: 李佳妍 | B12: 109 | C12: 118 | D12: 111 | E12: 90 | F12: 85 | G12: 83
A13: 李卓烜 | B13: 108 | C13: 115 | D13: 114 | E13: 89 | F13: 86 | G13: 84
A14: 李知与 | B14: 107 | C14: 114 | D14: 117 | E14: 85 | F14: 86 | G14: 86
... A807: 吴雪婷 | B807: 66 | C807: 16 | D807: 31 | E807: 23 | F807: 37 | G807: 37
A808: 许芷晴 | B808: 未扫，不计排名 | C808: 未扫，不计排名 | D808: 未扫，不计排名 | E808: 未扫，不计排名 | F808: 未扫，不计排名 | G808: 未扫，不计排名
A809: 朱恒锋 | B809: 未扫，不计排名 | C809: 未扫，不计排名 | D809: 未扫，不计排名 | E809: 未扫，不计排名 | F809: 未扫，不计排名 | G809: 未扫，不计排名
A810: 黄珷珺 | B810: 68 | C810: 77 | D810: 未扫，不计排名 | E810: 未扫，不计排名 | F810: 未扫，不计排名 | G810: 69
A811: 钟毓 | B811: 未扫，不计排名 | C811: 未扫，不计排名 | D811: 未扫，不计排名 | E811: 未扫，不计排名 | F811: 未扫，不计排名 | G811: 未扫，不计排名
A812: 许耀丹 | B812: 未扫，不计排名 | C812: 未扫，不计排名 | D812: 未扫，不计排名 | E812: 未扫，不计排名 | F812: 未扫，不计排名 | G812: 未扫，不计排名
A813: 张紫萱 | B813: 未扫，不计排名 | C813: 未扫，不计排名 | D813: 未扫，不计排名 | E813: 未扫，不计排名 | F813: 未扫，不计排名 | G813: 未扫，不计排名
A814: 黄睿曜 | B814: 86 | C814: 98 | D814: 未扫，不计排名 | E814: 未扫，不计排名 | F814: 未扫，不计排名 | G814: 82
