Workbook
Name 切片器_班型: #N/A
Name 九年级10班: 各班学生名单!$N$5:$N$49
Name 九年级11班: 各班学生名单!$O$5:$O$49
Name 九年级12班: 各班学生名单!$P$5:$P$49
Name 九年级13班: 各班学生名单!$Q$5:$Q$49
Name 九年级14班: 各班学生名单!$R$5:$R$49
Name 九年级15班: 各班学生名单!$S$5:$S$49
Name 九年级16班: 各班学生名单!$T$5:$T$49
Name 九年级17班: 各班学生名单!$U$5:$U$49
Name 九年级18班: 各班学生名单!$V$5:$V$49
Name 九年级19班: 各班学生名单!$W$5:$W$49
Name 九年级1班: 各班学生名单!$E$5:$E$49
Name 九年级2班: 各班学生名单!$F$5:$F$49
Name 九年级3班: 各班学生名单!$G$5:$G$49
Name 九年级4班: 各班学生名单!$H$5:$H$49
Name 九年级5班: 各班学生名单!$I$5:$I$49
Name 九年级6班: 各班学生名单!$J$5:$J$49
Name 九年级7班: 各班学生名单!$K$5:$K$49
Name 九年级8班: 各班学生名单!$L$5:$L$49
Name 九年级9班: 各班学生名单!$M$5:$M$49

Sheet 学生个人成绩分析看板
D2: =E4&" "&G4&" 学业水平跟踪档案统计与分析" -> 九年级19班 刘彧恺 学业水平跟踪档案统计与分析
D4: 班级 | E4: 九年级19班 | F4: 学生姓名 | G4: 刘彧恺 | H4: 考试日期 | I4: 46108 | L4: =_xlfn.XLOOKUP(G4,表成绩单[姓名],表成绩单[准考证号],"",0) -> 19173522
D6: 科目 | E6: 满分 | F6: 最高分 | G6: 平均分 | H6: 学生得分 | I6: 得分情况 | J6: 校排 | L6: 各科成绩分析-雷达图
D7: 语文 | E7: =_xlfn.XLOOKUP(学生个人成绩分析看板!$D7,表满分成绩[科目],表满分成绩[满分],"",0) -> 120 | F7: =IFERROR(_xlfn.MAXIFS(INDIRECT(_xlfn.CONCAT("表成绩单[",$D7,"]")),表成绩单[考试日期],$I$4),"") -> 117 | G7: =IFERROR(AVERAGEIFS(INDIRECT(_xlfn.CONCAT("表成绩单[",$D7,"]")),表成绩单[考试日期],$I$4),"") -> 93.876276 | H7: {=_xlfn.XLOOKUP($I$4&$L$4,表成绩单[考试日期]&表成绩单[准考证号],INDIRECT(_xlfn.CONCAT("表成绩单[",$D7,"]")),"",0)} -> 109 | I7: =IF(学生个人成绩分析看板!$H7>学生个人成绩分析看板!$G7,1,0) -> 1 | J7: {=_xlfn.XLOOKUP($I$4&$L$4,表成绩单[考试日期]&表成绩单[准考证号],INDIRECT(_xlfn.CONCAT("表成绩单[",$D7,"校排]")),"",0)} -> 40
D8: 数学 | E8: =_xlfn.XLOOKUP(学生个人成绩分析看板!$D8,表满分成绩[科目],表满分成绩[满分],"",0) -> 120 | F8: =IFERROR(_xlfn.MAXIFS(INDIRECT(_xlfn.CONCAT("表成绩单[",$D8,"]")),表成绩单[考试日期],$I$4),"") -> 113 | G8: =IFERROR(AVERAGEIFS(INDIRECT(_xlfn.CONCAT("表成绩单[",$D8,"]")),表成绩单[考试日期],$I$4),"") -> 85.765006 | H8: {=_xlfn.XLOOKUP($I$4&$L$4,表成绩单[考试日期]&表成绩单[准考证号],INDIRECT(_xlfn.CONCAT("表成绩单[",$D8,"]")),"",0)} -> 111 | I8: =IF(学生个人成绩分析看板!$H8>学生个人成绩分析看板!$G8,1,0) -> 1 | J8: {=_xlfn.XLOOKUP($I$4&$L$4,表成绩单[考试日期]&表成绩单[准考证号],INDIRECT(_xlfn.CONCAT("表成绩单[",$D8,"校排]")),"",0)} -> 7
D9: 英语 | E9: =_xlfn.XLOOKUP(学生个人成绩分析看板!$D9,表满分成绩[科目],表满分成绩[满分],"",0) -> 90 | F9: =IFERROR(_xlfn.MAXIFS(INDIRECT(_xlfn.CONCAT("表成绩单[",$D9,"]")),表成绩单[考试日期],$I$4),"") -> 88.5 | G9: =IFERROR(AVERAGEIFS(INDIRECT(_xlfn.CONCAT("表成绩单[",$D9,"]")),表成绩单[考试日期],$I$4),"") -> 71.749362 | H9: {=_xlfn.XLOOKUP($I$4&$L$4,表成绩单[考试日期]&表成绩单[准考证号],INDIRECT(_xlfn.CONCAT("表成绩单[",$D9,"]")),"",0)} -> 87.5 | I9: =IF(学生个人成绩分析看板!$H9>学生个人成绩分析看板!$G9,1,0) -> 1 | J9: {=_xlfn.XLOOKUP($I$4&$L$4,表成绩单[考试日期]&表成绩单[准考证号],INDIRECT(_xlfn.CONCAT("表成绩单[",$D9,"校排]")),"",0)} -> 6
D10: 物理 | E10: =_xlfn.XLOOKUP(学生个人成绩分析看板!$D10,表满分成绩[科目],表满分成绩[满分],"",0) -> 90 | F10: =IFERROR(_xlfn.MAXIFS(INDIRECT(_xlfn.CONCAT("表成绩单[",$D10,"]")),表成绩单[考试日期],$I$4),"") -> 90 | G10: =IFERROR(AVERAGEIFS(INDIRECT(_xlfn.CONCAT("表成绩单[",$D10,"]")),表成绩单[考试日期],$I$4),"") -> 73.664968 | H10: {=_xlfn.XLOOKUP($I$4&$L$4,表成绩单[考试日期]&表成绩单[准考证号],INDIRECT(_xlfn.CONCAT("表成绩单[",$D10,"]")),"",0)} -> 85 | I10: =IF(学生个人成绩分析看板!$H10>学生个人成绩分析看板!$G10,1,0) -> 1 | J10: {=_xlfn.XLOOKUP($I$4&$L$4,表成绩单[考试日期]&表成绩单[准考证号],INDIRECT(_xlfn.CONCAT("表成绩单[",$D10,"校排]")),"",0)} -> 105
D11: 化学 | E11: =_xlfn.XLOOKUP(学生个人成绩分析看板!$D11,表满分成绩[科目],表满分成绩[满分],"",0) -> 90 | F11: =IFERROR(_xlfn.MAXIFS(INDIRECT(_xlfn.CONCAT("表成绩单[",$D11,"]")),表成绩单[考试日期],$I$4),"") -> 89 | G11: =IFERROR(AVERAGEIFS(INDIRECT(_xlfn.CONCAT("表成绩单[",$D11,"]")),表成绩单[考试日期],$I$4),"") -> 62.152866 | H11: {=_xlfn.XLOOKUP($I$4&$L$4,表成绩单[考试日期]&表成绩单[准考证号],INDIRECT(_xlfn.CONCAT("表成绩单[",$D11,"]")),"",0)} -> 85 | I11: =IF(学生个人成绩分析看板!$H11>学生个人成绩分析看板!$G11,1,0) -> 1 | J11: {=_xlfn.XLOOKUP($I$4&$L$4,表成绩单[考试日期]&表成绩单[准考证号],INDIRECT(_xlfn.CONCAT("表成绩单[",$D11,"校排]")),"",0)} -> 4
D12: 政治 | E12: =_xlfn.XLOOKUP(学生个人成绩分析看板!$D12,表满分成绩[科目],表满分成绩[满分],"",0) -> 90 | F12: =IFERROR(_xlfn.MAXIFS(INDIRECT(_xlfn.CONCAT("表成绩单[",$D12,"]")),表成绩单[考试日期],$I$4),"") -> 88 | G12: =IFERROR(AVERAGEIFS(INDIRECT(_xlfn.CONCAT("表成绩单[",$D12,"]")),表成绩单[考试日期],$I$4),"") -> 72.446999 | H12: {=_xlfn.XLOOKUP($I$4&$L$4,表成绩单[考试日期]&表成绩单[准考证号],INDIRECT(_xlfn.CONCAT("表成绩单[",$D12,"]")),"",0)} -> 82 | I12: =IF(学生个人成绩分析看板!$H12>学生个人成绩分析看板!$G12,1,0) -> 1 | J12: {=_xlfn.XLOOKUP($I$4&$L$4,表成绩单[考试日期]&表成绩单[准考证号],INDIRECT(_xlfn.CONCAT("表成绩单[",$D12,"校排]")),"",0)} -> 45
D13: 历史 | E13: =_xlfn.XLOOKUP(学生个人成绩分析看板!$D13,表满分成绩[科目],表满分成绩[满分],"",0) -> 90 | F13: =IFERROR(_xlfn.MAXIFS(INDIRECT(_xlfn.CONCAT("表成绩单[",$D13,"]")),表成绩单[考试日期],$I$4),"") -> 88 | G13: =IFERROR(AVERAGEIFS(INDIRECT(_xlfn.CONCAT("表成绩单[",$D13,"]")),表成绩单[考试日期],$I$4),"") -> 73.020434 | H13: {=_xlfn.XLOOKUP($I$4&$L$4,表成绩单[考试日期]&表成绩单[准考证号],INDIRECT(_xlfn.CONCAT("表成绩单[",$D13,"]")),"",0)} -> 83 | I13: =IF(学生个人成绩分析看板!$H13>学生个人成绩分析看板!$G13,1,0) -> 1 | J13: {=_xlfn.XLOOKUP($I$4&$L$4,表成绩单[考试日期]&表成绩单[准考证号],INDIRECT(_xlfn.CONCAT("表成绩单[",$D13,"校排]")),"",0)} -> 60
D14: 总分 | E14: =SUBTOTAL(109,学生个人成绩分析看板!$E$7:$E$13) -> 690 | F14: =SUBTOTAL(109,学生个人成绩分析看板!$F$7:$F$13) -> 673.5 | G14: =SUBTOTAL(101,学生个人成绩分析看板!$G$7:$G$13) -> 76.096559 | H14: =SUBTOTAL(109,学生个人成绩分析看板!$H$7:$H$13) -> 642.5 | I14: =IF(学生个人成绩分析看板!$H$14>学生个人成绩分析看板!$G$14,1,0) -> 1 | J14: {=_xlfn.XLOOKUP($I$4&$L$4,表成绩单[考试日期]&表成绩单[准考证号],INDIRECT(_xlfn.CONCAT("表成绩单[",$D13,"校排]")),"",0)} -> 60
D16: 排行榜分析
D19: 成绩对比分析（得分）
D22: 成绩对比分析（排名）

Sheet 学生个人成绩统计表
D2: =F4&" "&K4&" 个人成绩统计表" -> 九年级11班 罗加薇 个人成绩统计表
D4: 学生班级： | F4: 九年级11班 | H4: 学生姓名： | K4: 罗加薇 | N4: 准考证号： | Q4: =_xlfn.XLOOKUP(K4,表成绩单[姓名],表成绩单[准考证号],"",0) -> 19178630
D5: 考试日期 | E5: 参考人数 | F5: 班级 | G5: 语文 | H5: 语文校排 | I5: 数学 | J5: 数学校排 | K5: 英语 | L5: 英语校排 | M5: 物理 | N5: 物理校排 | O5: 化学 | P5: 化学校排 | Q5: 政治 | R5: 政治校排 | S5: 历史 | T5: 历史校排 | U5: 总分 | V5: 总分校排
D6: 45975 | E6: =IF(表7[[#This Row],[考试日期]]="","",COUNTIFS(表成绩单[考试日期],表7[[#This Row],[考试日期]])) -> 801 | F6: =IF(表7[[#This Row],[考试日期]]="","",$F$4) -> 九年级11班 | G6: {=_xlfn.XLOOKUP(表7[[#This Row],[考试日期]]&$Q$4,表成绩单[考试日期]&表成绩单[准考证号],INDIRECT(_xlfn.CONCAT("表成绩单[",G$5,"]")),"",0)} -> 104 | H6: {=_xlfn.XLOOKUP(表7[[#This Row],[考试日期]]&$Q$4,表成绩单[考试日期]&表成绩单[准考证号],INDIRECT(_xlfn.CONCAT("表成绩单[",H$5,"]")),"",0)} -> 104 | I6: {=_xlfn.XLOOKUP(表7[[#This Row],[考试日期]]&$Q$4,表成绩单[考试日期]&表成绩单[准考证号],INDIRECT(_xlfn.CONCAT("表成绩单[",I$5,"]")),"",0)} -> 109 | J6: {=_xlfn.XLOOKUP(表7[[#This Row],[考试日期]]&$Q$4,表成绩单[考试日期]&表成绩单[准考证号],INDIRECT(_xlfn.CONCAT("表成绩单[",J$5,"]")),"",0)} -> 165 | K6: {=_xlfn.XLOOKUP(表7[[#This Row],[考试日期]]&$Q$4,表成绩单[考试日期]&表成绩单[准考证号],INDIRECT(_xlfn.CONCAT("表成绩单[",K$5,"]")),"",0)} -> 81 | L6: {=_xlfn.XLOOKUP(表7[[#This Row],[考试日期]]&$Q$4,表成绩单[考试日期]&表成绩单[准考证号],INDIRECT(_xlfn.CONCAT("表成绩单[",L$5,"]")),"",0)} -> 241 | M6: {=_xlfn.XLOOKUP(表7[[#This Row],[考试日期]]&$Q$4,表成绩单[考试日期]&表成绩单[准考证号],INDIRECT(_xlfn.CONCAT("表成绩单[",M$5,"]")),"",0)} -> 85 | N6: {=_xlfn.XLOOKUP(表7[[#This Row],[考试日期]]&$Q$4,表成绩单[考试日期]&表成绩单[准考证号],INDIRECT(_xlfn.CONCAT("表成绩单[",N$5,"]")),"",0)} -> 263 | ... V6: {=_xlfn.XLOOKUP(表7[[#This Row],[考试日期]]&$Q$4,表成绩单[考试日期]&表成绩单[准考证号],INDIRECT(_xlfn.CONCAT("表成绩单[",V$5,"]")),"",0)} -> 136
D7: 46003 | E7: =IF(表7[[#This Row],[考试日期]]="","",COUNTIFS(表成绩单[考试日期],表7[[#This Row],[考试日期]])) -> 801 | F7: =IF(表7[[#This Row],[考试日期]]="","",$F$4) -> 九年级11班 | G7: {=_xlfn.XLOOKUP(表7[[#This Row],[考试日期]]&$Q$4,表成绩单[考试日期]&表成绩单[准考证号],INDIRECT(_xlfn.CONCAT("表成绩单[",G$5,"]")),"",0)} -> 106 | H7: {=_xlfn.XLOOKUP(表7[[#This Row],[考试日期]]&$Q$4,表成绩单[考试日期]&表成绩单[准考证号],INDIRECT(_xlfn.CONCAT("表成绩单[",H$5,"]")),"",0)} -> 210 | I7: {=_xlfn.XLOOKUP(表7[[#This Row],[考试日期]]&$Q$4,表成绩单[考试日期]&表成绩单[准考证号],INDIRECT(_xlfn.CONCAT("表成绩单[",I$5,"]")),"",0)} -> 87 | J7: {=_xlfn.XLOOKUP(表7[[#This Row],[考试日期]]&$Q$4,表成绩单[考试日期]&表成绩单[准考证号],INDIRECT(_xlfn.CONCAT("表成绩单[",J$5,"]")),"",0)} -> 223 | K7: {=_xlfn.XLOOKUP(表7[[#This Row],[考试日期]]&$Q$4,表成绩单[考试日期]&表成绩单[准考证号],INDIRECT(_xlfn.CONCAT("表成绩单[",K$5,"]")),"",0)} -> 84.5 | L7: {=_xlfn.XLOOKUP(表7[[#This Row],[考试日期]]&$Q$4,表成绩单[考试日期]&表成绩单[准考证号],INDIRECT(_xlfn.CONCAT("表成绩单[",L$5,"]")),"",0)} -> 37 | M7: {=_xlfn.XLOOKUP(表7[[#This Row],[考试日期]]&$Q$4,表成绩单[考试日期]&表成绩单[准考证号],INDIRECT(_xlfn.CONCAT("表成绩单[",M$5,"]")),"",0)} -> 94 | N7: {=_xlfn.XLOOKUP(表7[[#This Row],[考试日期]]&$Q$4,表成绩单[考试日期]&表成绩单[准考证号],INDIRECT(_xlfn.CONCAT("表成绩单[",N$5,"]")),"",0)} -> 125 | ... V7: {=_xlfn.XLOOKUP(表7[[#This Row],[考试日期]]&$Q$4,表成绩单[考试日期]&表成绩单[准考证号],INDIRECT(_xlfn.CONCAT("表成绩单[",V$5,"]")),"",0)} -> 107
D8: 46030 | E8: =IF(表7[[#This Row],[考试日期]]="","",COUNTIFS(表成绩单[考试日期],表7[[#This Row],[考试日期]])) -> 801 | F8: =IF(表7[[#This Row],[考试日期]]="","",$F$4) -> 九年级11班 | G8: {=_xlfn.XLOOKUP(表7[[#This Row],[考试日期]]&$Q$4,表成绩单[考试日期]&表成绩单[准考证号],INDIRECT(_xlfn.CONCAT("表成绩单[",G$5,"]")),"",0)} -> 102 | H8: {=_xlfn.XLOOKUP(表7[[#This Row],[考试日期]]&$Q$4,表成绩单[考试日期]&表成绩单[准考证号],INDIRECT(_xlfn.CONCAT("表成绩单[",H$5,"]")),"",0)} -> 132 | I8: {=_xlfn.XLOOKUP(表7[[#This Row],[考试日期]]&$Q$4,表成绩单[考试日期]&表成绩单[准考证号],INDIRECT(_xlfn.CONCAT("表成绩单[",I$5,"]")),"",0)} -> 102 | J8: {=_xlfn.XLOOKUP(表7[[#This Row],[考试日期]]&$Q$4,表成绩单[考试日期]&表成绩单[准考证号],INDIRECT(_xlfn.CONCAT("表成绩单[",J$5,"]")),"",0)} -> 95 | K8: {=_xlfn.XLOOKUP(表7[[#This Row],[考试日期]]&$Q$4,表成绩单[考试日期]&表成绩单[准考证号],INDIRECT(_xlfn.CONCAT("表成绩单[",K$5,"]")),"",0)} -> 76.5 | L8: {=_xlfn.XLOOKUP(表7[[#This Row],[考试日期]]&$Q$4,表成绩单[考试日期]&表成绩单[准考证号],INDIRECT(_xlfn.CONCAT("表成绩单[",L$5,"]")),"",0)} -> 120 | M8: {=_xlfn.XLOOKUP(表7[[#This Row],[考试日期]]&$Q$4,表成绩单[考试日期]&表成绩单[准考证号],INDIRECT(_xlfn.CONCAT("表成绩单[",M$5,"]")),"",0)} -> 79 | N8: {=_xlfn.XLOOKUP(表7[[#This Row],[考试日期]]&$Q$4,表成绩单[考试日期]&表成绩单[准考证号],INDIRECT(_xlfn.CONCAT("表成绩单[",N$5,"]")),"",0)} -> 153 | ... V8: {=_xlfn.XLOOKUP(表7[[#This Row],[考试日期]]&$Q$4,表成绩单[考试日期]&表成绩单[准考证号],INDIRECT(_xlfn.CONCAT("表成绩单[",V$5,"]")),"",0)} -> 62
D9: 46108 | E9: =IF(表7[[#This Row],[考试日期]]="","",COUNTIFS(表成绩单[考试日期],表7[[#This Row],[考试日期]])) -> 798 | F9: =IF(表7[[#This Row],[考试日期]]="","",$F$4) -> 九年级11班 | G9: {=_xlfn.XLOOKUP(表7[[#This Row],[考试日期]]&$Q$4,表成绩单[考试日期]&表成绩单[准考证号],INDIRECT(_xlfn.CONCAT("表成绩单[",G$5,"]")),"",0)} -> 104 | H9: {=_xlfn.XLOOKUP(表7[[#This Row],[考试日期]]&$Q$4,表成绩单[考试日期]&表成绩单[准考证号],INDIRECT(_xlfn.CONCAT("表成绩单[",H$5,"]")),"",0)} -> 131 | I9: {=_xlfn.XLOOKUP(表7[[#This Row],[考试日期]]&$Q$4,表成绩单[考试日期]&表成绩单[准考证号],INDIRECT(_xlfn.CONCAT("表成绩单[",I$5,"]")),"",0)} -> 104 | J9: {=_xlfn.XLOOKUP(表7[[#This Row],[考试日期]]&$Q$4,表成绩单[考试日期]&表成绩单[准考证号],INDIRECT(_xlfn.CONCAT("表成绩单[",J$5,"]")),"",0)} -> 68 | K9: {=_xlfn.XLOOKUP(表7[[#This Row],[考试日期]]&$Q$4,表成绩单[考试日期]&表成绩单[准考证号],INDIRECT(_xlfn.CONCAT("表成绩单[",K$5,"]")),"",0)} -> 83 | L9: {=_xlfn.XLOOKUP(表7[[#This Row],[考试日期]]&$Q$4,表成绩单[考试日期]&表成绩单[准考证号],INDIRECT(_xlfn.CONCAT("表成绩单[",L$5,"]")),"",0)} -> 134 | M9: {=_xlfn.XLOOKUP(表7[[#This Row],[考试日期]]&$Q$4,表成绩单[考试日期]&表成绩单[准考证号],INDIRECT(_xlfn.CONCAT("表成绩单[",M$5,"]")),"",0)} -> 86 | N9: {=_xlfn.XLOOKUP(表7[[#This Row],[考试日期]]&$Q$4,表成绩单[考试日期]&表成绩单[准考证号],INDIRECT(_xlfn.CONCAT("表成绩单[",N$5,"]")),"",0)} -> 61 | ... V9: {=_xlfn.XLOOKUP(表7[[#This Row],[考试日期]]&$Q$4,表成绩单[考试日期]&表成绩单[准考证号],INDIRECT(_xlfn.CONCAT("表成绩单[",V$5,"]")),"",0)} -> 31
E10: =IF(表7[[#This Row],[考试日期]]="","",COUNTIFS(表成绩单[考试日期],表7[[#This Row],[考试日期]])) | F10: =IF(表7[[#This Row],[考试日期]]="","",$F$4) | G10: {=_xlfn.XLOOKUP(表7[[#This Row],[考试日期]]&$Q$4,表成绩单[考试日期]&表成绩单[准考证号],INDIRECT(_xlfn.CONCAT("表成绩单[",G$5,"]")),"",0)} | H10: {=_xlfn.XLOOKUP(表7[[#This Row],[考试日期]]&$Q$4,表成绩单[考试日期]&表成绩单[准考证号],INDIRECT(_xlfn.CONCAT("表成绩单[",H$5,"]")),"",0)} | I10: {=_xlfn.XLOOKUP(表7[[#This Row],[考试日期]]&$Q$4,表成绩单[考试日期]&表成绩单[准考证号],INDIRECT(_xlfn.CONCAT("表成绩单[",I$5,"]")),"",0)} | J10: {=_xlfn.XLOOKUP(表7[[#This Row],[考试日期]]&$Q$4,表成绩单[考试日期]&表成绩单[准考证号],INDIRECT(_xlfn.CONCAT("表成绩单[",J$5,"]")),"",0)} | K10: {=_xlfn.XLOOKUP(表7[[#This Row],[考试日期]]&$Q$4,表成绩单[考试日期]&表成绩单[准考证号],INDIRECT(_xlfn.CONCAT("表成绩单[",K$5,"]")),"",0)} | L10: {=_xlfn.XLOOKUP(表7[[#This Row],[考试日期]]&$Q$4,表成绩单[考试日期]&表成绩单[准考证号],INDIRECT(_xlfn.CONCAT("表成绩单[",L$5,"]")),"",0)} | M10: {=_xlfn.XLOOKUP(表7[[#This Row],[考试日期]]&$Q$4,表成绩单[考试日期]&表成绩单[准考证号],INDIRECT(_xlfn.CONCAT("表成绩单[",M$5,"]")),"",0)} | N10: {=_xlfn.XLOOKUP(表7[[#This Row],[考试日期]]&$Q$4,表成绩单[考试日期]&表成绩单[准考证号],INDIRECT(_xlfn.CONCAT("表成绩单[",N$5,"]")),"",0)} | ... V10: {=_xlfn.XLOOKUP(表7[[#This Row],[考试日期]]&$Q$4,表成绩单[考试日期]&表成绩单[准考证号],INDIRECT(_xlfn.CONCAT("表成绩单[",V$5,"]")),"",0)}
E11: =IF(表7[[#This Row],[考试日期]]="","",COUNTIFS(表成绩单[考试日期],表7[[#This Row],[考试日期]])) | F11: =IF(表7[[#This Row],[考试日期]]="","",$F$4) | G11: {=_xlfn.XLOOKUP(表7[[#This Row],[考试日期]]&$Q$4,表成绩单[考试日期]&表成绩单[准考证号],INDIRECT(_xlfn.CONCAT("表成绩单[",G$5,"]")),"",0)} | H11: {=_xlfn.XLOOKUP(表7[[#This Row],[考试日期]]&$Q$4,表成绩单[考试日期]&表成绩单[准考证号],INDIRECT(_xlfn.CONCAT("表成绩单[",H$5,"]")),"",0)} | I11: {=_xlfn.XLOOKUP(表7[[#This Row],[考试日期]]&$Q$4,表成绩单[考试日期]&表成绩单[准考证号],INDIRECT(_xlfn.CONCAT("表成绩单[",I$5,"]")),"",0)} | J11: {=_xlfn.XLOOKUP(表7[[#This Row],[考试日期]]&$Q$4,表成绩单[考试日期]&表成绩单[准考证号],INDIRECT(_xlfn.CONCAT("表成绩单[",J$5,"]")),"",0)} | K11: {=_xlfn.XLOOKUP(表7[[#This Row],[考试日期]]&$Q$4,表成绩单[考试日期]&表成绩单[准考证号],INDIRECT(_xlfn.CONCAT("表成绩单[",K$5,"]")),"",0)} | L11: {=_xlfn.XLOOKUP(表7[[#This Row],[考试日期]]&$Q$4,表成绩单[考试日期]&表成绩单[准考证号],INDIRECT(_xlfn.CONCAT("表成绩单[",L$5,"]")),"",0)} | M11: {=_xlfn.XLOOKUP(表7[[#This Row],[考试日期]]&$Q$4,表成绩单[考试日期]&表成绩单[准考证号],INDIRECT(_xlfn.CONCAT("表成绩单[",M$5,"]")),"",0)} | N11: {=_xlfn.XLOOKUP(表7[[#This Row],[考试日期]]&$Q$4,表成绩单[考试日期]&表成绩单[准考证号],INDIRECT(_xlfn.CONCAT("表成绩单[",N$5,"]")),"",0)} | ... V11: {=_xlfn.XLOOKUP(表7[[#This Row],[考试日期]]&$Q$4,表成绩单[考试日期]&表成绩单[准考证号],INDIRECT(_xlfn.CONCAT("表成绩单[",V$5,"]")),"",0)}
F12: 均分 | G12: =SUBTOTAL(101,表7[语文]) -> 104 | H12: =SUBTOTAL(101,表7[语文校排]) -> 144.25 | I12: =SUBTOTAL(101,表7[数学]) -> 100.5 | J12: =SUBTOTAL(101,表7[数学校排]) -> 137.75 | K12: =SUBTOTAL(101,表7[英语]) -> 81.25 | L12: =SUBTOTAL(101,表7[英语校排]) -> 133 | M12: =SUBTOTAL(101,表7[物理]) -> 86 | N12: =SUBTOTAL(101,表7[物理校排]) -> 150.5 | O12: =SUBTOTAL(101,表7[化学]) -> 79.75 | P12: =SUBTOTAL(101,表7[化学校排]) -> 159.75 | Q12: =SUBTOTAL(101,表7[政治]) -> 81.25 | R12: =SUBTOTAL(101,表7[政治校排]) -> 74.25 | S12: =SUBTOTAL(101,表7[历史]) -> 80.75 | T12: =SUBTOTAL(101,表7[历史校排]) -> 95.25 | U12: =SUBTOTAL(101,表7[总分]) -> 613.5 | V12: =SUBTOTAL(101,表7[总分校排]) -> 84
D13: 签名（分管领导）： | O13: 盖章（学校公章）：

Sheet 教学质量分析
D1: 返回◀
D2: （九年级）教学质量分析
D4: 请选科目👉 | F4: 政治 | G4: 请选择日期 | I4: 46108 | K4: 高分明细👉 | M4: =VLOOKUP($F$4,表满分成绩[#Data],3,0) -> 76.5 | N4: =VLOOKUP($F$4,表满分成绩[#Data],4,0) -> 72 | O4: =VLOOKUP($F$4,表满分成绩[#Data],5,0) -> 54 | P4: 123
D6: 序号 | E6: 班级 | F6: 班型 | G6: 参考人数 | H6: 最高分 | I6: 平均分 | J6: 超均率 | K6: 优秀人数 | L6: 优秀率% | M6: 良好人数 | N6: 良好率% | O6: 及格人数 | P6: 及格率%
D7: =ROW()-6 -> 1 | E7: 九年级1班 | F7: 创新班 | G7: {=COUNT(_xlfn.LET(_xlpm.CJ,INDIRECT(_xlfn.CONCAT("表成绩单[",$F$4,"]")),_xlfn._xlws.FILTER(_xlpm.CJ,(表成绩单[班级]=$E7)*(表成绩单[考试日期]=$I$4))))} -> 39 | H7: {=IFERROR(MAX(_xlfn.LET(_xlpm.CJ,INDIRECT(_xlfn.CONCAT("表成绩单[",$F$4,"]")),_xlfn._xlws.FILTER(_xlpm.CJ,(表成绩单[班级]=$E7)*(表成绩单[考试日期]=$I$4)))),"")} -> 81 | I7: {=IFERROR(AVERAGE(_xlfn.LET(_xlpm.CJ,INDIRECT(_xlfn.CONCAT("表成绩单[",$F$4,"]")),_xlfn._xlws.FILTER(_xlpm.CJ,(表成绩单[班级]=$E7)*(表成绩单[考试日期]=$I$4)))),"")} -> 65.435897 | J7: =IFERROR((表教学质量[[#This Row],[平均分]]-表教学质量[[#Totals],[平均分]])/表教学质量[[#Totals],[平均分]],"") -> -0.094974584 | K7: {=COUNT(_xlfn.LET(_xlpm.CJ,INDIRECT(_xlfn.CONCAT("表成绩单[",$F$4,"]")),_xlfn._xlws.FILTER(_xlpm.CJ,(表成绩单[班级]=$E7)*(_xlpm.CJ>=$M$4)*(表成绩单[考试日期]=$I$4))))} -> 3 | L7: =表教学质量[[#This Row],[优秀人数]]/表教学质量[[#This Row],[参考人数]] -> 0.076923077 | M7: {=COUNT(_xlfn.LET(_xlpm.CJ,INDIRECT(_xlfn.CONCAT("表成绩单[",$F$4,"]")),_xlfn._xlws.FILTER(_xlpm.CJ,(表成绩单[班级]=$E7)*(_xlpm.CJ>=$N$4)*(表成绩单[考试日期]=$I$4))))} -> 15 | N7: =表教学质量[[#This Row],[良好人数]]/表教学质量[[#This Row],[参考人数]] -> 0.38461538 | O7: {=COUNT(_xlfn.LET(_xlpm.CJ,INDIRECT(_xlfn.CONCAT("表成绩单[",$F$4,"]")),_xlfn._xlws.FILTER(_xlpm.CJ,(表成绩单[班级]=$E7)*(_xlpm.CJ>=$O$4)*(表成绩单[考试日期]=$I$4))))} -> 34 | P7: =表教学质量[[#This Row],[及格人数]]/表教学质量[[#This Row],[参考人数]] -> 0.87179487
D8: =ROW()-6 -> 2 | E8: 九年级2班 | F8: 创新班 | G8: {=COUNT(_xlfn.LET(_xlpm.CJ,INDIRECT(_xlfn.CONCAT("表成绩单[",$F$4,"]")),_xlfn._xlws.FILTER(_xlpm.CJ,(表成绩单[班级]=$E8)*(表成绩单[考试日期]=$I$4))))} -> 41 | H8: {=IFERROR(MAX(_xlfn.LET(_xlpm.CJ,INDIRECT(_xlfn.CONCAT("表成绩单[",$F$4,"]")),_xlfn._xlws.FILTER(_xlpm.CJ,(表成绩单[班级]=$E8)*(表成绩单[考试日期]=$I$4)))),"")} -> 77 | I8: {=IFERROR(AVERAGE(_xlfn.LET(_xlpm.CJ,INDIRECT(_xlfn.CONCAT("表成绩单[",$F$4,"]")),_xlfn._xlws.FILTER(_xlpm.CJ,(表成绩单[班级]=$E8)*(表成绩单[考试日期]=$I$4)))),"")} -> 65.731707 | J8: =IFERROR((表教学质量[[#This Row],[平均分]]-表教学质量[[#Totals],[平均分]])/表教学质量[[#Totals],[平均分]],"") -> -0.090883321 | K8: {=COUNT(_xlfn.LET(_xlpm.CJ,INDIRECT(_xlfn.CONCAT("表成绩单[",$F$4,"]")),_xlfn._xlws.FILTER(_xlpm.CJ,(表成绩单[班级]=$E8)*(_xlpm.CJ>=$M$4)*(表成绩单[考试日期]=$I$4))))} -> 2 | L8: =表教学质量[[#This Row],[优秀人数]]/表教学质量[[#This Row],[参考人数]] -> 0.048780488 | M8: {=COUNT(_xlfn.LET(_xlpm.CJ,INDIRECT(_xlfn.CONCAT("表成绩单[",$F$4,"]")),_xlfn._xlws.FILTER(_xlpm.CJ,(表成绩单[班级]=$E8)*(_xlpm.CJ>=$N$4)*(表成绩单[考试日期]=$I$4))))} -> 15 | N8: =表教学质量[[#This Row],[良好人数]]/表教学质量[[#This Row],[参考人数]] -> 0.36585366 | O8: {=COUNT(_xlfn.LET(_xlpm.CJ,INDIRECT(_xlfn.CONCAT("表成绩单[",$F$4,"]")),_xlfn._xlws.FILTER(_xlpm.CJ,(表成绩单[班级]=$E8)*(_xlpm.CJ>=$O$4)*(表成绩单[考试日期]=$I$4))))} -> 34 | P8: =表教学质量[[#This Row],[及格人数]]/表教学质量[[#This Row],[参考人数]] -> 0.82926829
D9: =ROW()-6 -> 3 | E9: 九年级3班 | F9: 创新班 | G9: {=COUNT(_xlfn.LET(_xlpm.CJ,INDIRECT(_xlfn.CONCAT("表成绩单[",$F$4,"]")),_xlfn._xlws.FILTER(_xlpm.CJ,(表成绩单[班级]=$E9)*(表成绩单[考试日期]=$I$4))))} -> 39 | H9: {=IFERROR(MAX(_xlfn.LET(_xlpm.CJ,INDIRECT(_xlfn.CONCAT("表成绩单[",$F$4,"]")),_xlfn._xlws.FILTER(_xlpm.CJ,(表成绩单[班级]=$E9)*(表成绩单[考试日期]=$I$4)))),"")} -> 80 | I9: {=IFERROR(AVERAGE(_xlfn.LET(_xlpm.CJ,INDIRECT(_xlfn.CONCAT("表成绩单[",$F$4,"]")),_xlfn._xlws.FILTER(_xlpm.CJ,(表成绩单[班级]=$E9)*(表成绩单[考试日期]=$I$4)))),"")} -> 62.948718 | J9: =IFERROR((表教学质量[[#This Row],[平均分]]-表教学质量[[#Totals],[平均分]])/表教学质量[[#Totals],[平均分]],"") -> -0.12937406 | K9: {=COUNT(_xlfn.LET(_xlpm.CJ,INDIRECT(_xlfn.CONCAT("表成绩单[",$F$4,"]")),_xlfn._xlws.FILTER(_xlpm.CJ,(表成绩单[班级]=$E9)*(_xlpm.CJ>=$M$4)*(表成绩单[考试日期]=$I$4))))} -> 2 | L9: =表教学质量[[#This Row],[优秀人数]]/表教学质量[[#This Row],[参考人数]] -> 0.051282051 | M9: {=COUNT(_xlfn.LET(_xlpm.CJ,INDIRECT(_xlfn.CONCAT("表成绩单[",$F$4,"]")),_xlfn._xlws.FILTER(_xlpm.CJ,(表成绩单[班级]=$E9)*(_xlpm.CJ>=$N$4)*(表成绩单[考试日期]=$I$4))))} -> 12 | N9: =表教学质量[[#This Row],[良好人数]]/表教学质量[[#This Row],[参考人数]] -> 0.30769231 | O9: {=COUNT(_xlfn.LET(_xlpm.CJ,INDIRECT(_xlfn.CONCAT("表成绩单[",$F$4,"]")),_xlfn._xlws.FILTER(_xlpm.CJ,(表成绩单[班级]=$E9)*(_xlpm.CJ>=$O$4)*(表成绩单[考试日期]=$I$4))))} -> 33 | P9: =表教学质量[[#This Row],[及格人数]]/表教学质量[[#This Row],[参考人数]] -> 0.84615385
D10: =ROW()-6 -> 4 | E10: 九年级4班 | F10: 创新班 | G10: {=COUNT(_xlfn.LET(_xlpm.CJ,INDIRECT(_xlfn.CONCAT("表成绩单[",$F$4,"]")),_xlfn._xlws.FILTER(_xlpm.CJ,(表成绩单[班级]=$E10)*(表成绩单[考试日期]=$I$4))))} -> 41 | H10: {=IFERROR(MAX(_xlfn.LET(_xlpm.CJ,INDIRECT(_xlfn.CONCAT("表成绩单[",$F$4,"]")),_xlfn._xlws.FILTER(_xlpm.CJ,(表成绩单[班级]=$E10)*(表成绩单[考试日期]=$I$4)))),"")} -> 81 | I10: {=IFERROR(AVERAGE(_xlfn.LET(_xlpm.CJ,INDIRECT(_xlfn.CONCAT("表成绩单[",$F$4,"]")),_xlfn._xlws.FILTER(_xlpm.CJ,(表成绩单[班级]=$E10)*(表成绩单[考试日期]=$I$4)))),"")} -> 65.829268 | J10: =IFERROR((表教学质量[[#This Row],[平均分]]-表教学质量[[#Totals],[平均分]])/表教学质量[[#Totals],[平均分]],"") -> -0.089533982 | K10: {=COUNT(_xlfn.LET(_xlpm.CJ,INDIRECT(_xlfn.CONCAT("表成绩单[",$F$4,"]")),_xlfn._xlws.FILTER(_xlpm.CJ,(表成绩单[班级]=$E10)*(_xlpm.CJ>=$M$4)*(表成绩单[考试日期]=$I$4))))} -> 5 | L10: =表教学质量[[#This Row],[优秀人数]]/表教学质量[[#This Row],[参考人数]] -> 0.12195122 | M10: {=COUNT(_xlfn.LET(_xlpm.CJ,INDIRECT(_xlfn.CONCAT("表成绩单[",$F$4,"]")),_xlfn._xlws.FILTER(_xlpm.CJ,(表成绩单[班级]=$E10)*(_xlpm.CJ>=$N$4)*(表成绩单[考试日期]=$I$4))))} -> 16 | N10: =表教学质量[[#This Row],[良好人数]]/表教学质量[[#This Row],[参考人数]] -> 0.3902439 | O10: {=COUNT(_xlfn.LET(_xlpm.CJ,INDIRECT(_xlfn.CONCAT("表成绩单[",$F$4,"]")),_xlfn._xlws.FILTER(_xlpm.CJ,(表成绩单[班级]=$E10)*(_xlpm.CJ>=$O$4)*(表成绩单[考试日期]=$I$4))))} -> 34 | P10: =表教学质量[[#This Row],[及格人数]]/表教学质量[[#This Row],[参考人数]] -> 0.82926829
D11: =ROW()-6 -> 5 | E11: 九年级5班 | F11: 创新班 | G11: {=COUNT(_xlfn.LET(_xlpm.CJ,INDIRECT(_xlfn.CONCAT("表成绩单[",$F$4,"]")),_xlfn._xlws.FILTER(_xlpm.CJ,(表成绩单[班级]=$E11)*(表成绩单[考试日期]=$I$4))))} -> 35 | H11: {=IFERROR(MAX(_xlfn.LET(_xlpm.CJ,INDIRECT(_xlfn.CONCAT("表成绩单[",$F$4,"]")),_xlfn._xlws.FILTER(_xlpm.CJ,(表成绩单[班级]=$E11)*(表成绩单[考试日期]=$I$4)))),"")} -> 79 | I11: {=IFERROR(AVERAGE(_xlfn.LET(_xlpm.CJ,INDIRECT(_xlfn.CONCAT("表成绩单[",$F$4,"]")),_xlfn._xlws.FILTER(_xlpm.CJ,(表成绩单[班级]=$E11)*(表成绩单[考试日期]=$I$4)))),"")} -> 64.742857 | J11: =IFERROR((表教学质量[[#This Row],[平均分]]-表教学质量[[#Totals],[平均分]])/表教学质量[[#Totals],[平均分]],"") -> -0.10455983 | K11: {=COUNT(_xlfn.LET(_xlpm.CJ,INDIRECT(_xlfn.CONCAT("表成绩单[",$F$4,"]")),_xlfn._xlws.FILTER(_xlpm.CJ,(表成绩单[班级]=$E11)*(_xlpm.CJ>=$M$4)*(表成绩单[考试日期]=$I$4))))} -> 1 | L11: =表教学质量[[#This Row],[优秀人数]]/表教学质量[[#This Row],[参考人数]] -> 0.028571429 | M11: {=COUNT(_xlfn.LET(_xlpm.CJ,INDIRECT(_xlfn.CONCAT("表成绩单[",$F$4,"]")),_xlfn._xlws.FILTER(_xlpm.CJ,(表成绩单[班级]=$E11)*(_xlpm.CJ>=$N$4)*(表成绩单[考试日期]=$I$4))))} -> 9 | N11: =表教学质量[[#This Row],[良好人数]]/表教学质量[[#This Row],[参考人数]] -> 0.25714286 | O11: {=COUNT(_xlfn.LET(_xlpm.CJ,INDIRECT(_xlfn.CONCAT("表成绩单[",$F$4,"]")),_xlfn._xlws.FILTER(_xlpm.CJ,(表成绩单[班级]=$E11)*(_xlpm.CJ>=$O$4)*(表成绩单[考试日期]=$I$4))))} -> 30 | P11: =表教学质量[[#This Row],[及格人数]]/表教学质量[[#This Row],[参考人数]] -> 0.85714286
D12: =ROW()-6 -> 6 | E12: 九年级6班 | F12: 格知班 | G12: {=COUNT(_xlfn.LET(_xlpm.CJ,INDIRECT(_xlfn.CONCAT("表成绩单[",$F$4,"]")),_xlfn._xlws.FILTER(_xlpm.CJ,(表成绩单[班级]=$E12)*(表成绩单[考试日期]=$I$4))))} -> 45 | H12: {=IFERROR(MAX(_xlfn.LET(_xlpm.CJ,INDIRECT(_xlfn.CONCAT("表成绩单[",$F$4,"]")),_xlfn._xlws.FILTER(_xlpm.CJ,(表成绩单[班级]=$E12)*(表成绩单[考试日期]=$I$4)))),"")} -> 80 | I12: {=IFERROR(AVERAGE(_xlfn.LET(_xlpm.CJ,INDIRECT(_xlfn.CONCAT("表成绩单[",$F$4,"]")),_xlfn._xlws.FILTER(_xlpm.CJ,(表成绩单[班级]=$E12)*(表成绩单[考试日期]=$I$4)))),"")} -> 70.355556 | J12: =IFERROR((表教学质量[[#This Row],[平均分]]-表教学质量[[#Totals],[平均分]])/表教学质量[[#Totals],[平均分]],"") -> -0.026932182 | K12: {=COUNT(_xlfn.LET(_xlpm.CJ,INDIRECT(_xlfn.CONCAT("表成绩单[",$F$4,"]")),_xlfn._xlws.FILTER(_xlpm.CJ,(表成绩单[班级]=$E12)*(_xlpm.CJ>=$M$4)*(表成绩单[考试日期]=$I$4))))} -> 8 | L12: =表教学质量[[#This Row],[优秀人数]]/表教学质量[[#This Row],[参考人数]] -> 0.17777778 | M12: {=COUNT(_xlfn.LET(_xlpm.CJ,INDIRECT(_xlfn.CONCAT("表成绩单[",$F$4,"]")),_xlfn._xlws.FILTER(_xlpm.CJ,(表成绩单[班级]=$E12)*(_xlpm.CJ>=$N$4)*(表成绩单[考试日期]=$I$4))))} -> 22 | N12: =表教学质量[[#This Row],[良好人数]]/表教学质量[[#This Row],[参考人数]] -> 0.48888889 | O12: {=COUNT(_xlfn.LET(_xlpm.CJ,INDIRECT(_xlfn.CONCAT("表成绩单[",$F$4,"]")),_xlfn._xlws.FILTER(_xlpm.CJ,(表成绩单[班级]=$E12)*(_xlpm.CJ>=$O$4)*(表成绩单[考试日期]=$I$4))))} -> 44 | P12: =表教学质量[[#This Row],[及格人数]]/表教学质量[[#This Row],[参考人数]] -> 0.97777778
D13: =ROW()-6 -> 7 | E13: 九年级7班 | F13: 格知班 | G13: {=COUNT(_xlfn.LET(_xlpm.CJ,INDIRECT(_xlfn.CONCAT("表成绩单[",$F$4,"]")),_xlfn._xlws.FILTER(_xlpm.CJ,(表成绩单[班级]=$E13)*(表成绩单[考试日期]=$I$4))))} -> 45 | H13: {=IFERROR(MAX(_xlfn.LET(_xlpm.CJ,INDIRECT(_xlfn.CONCAT("表成绩单[",$F$4,"]")),_xlfn._xlws.FILTER(_xlpm.CJ,(表成绩单[班级]=$E13)*(表成绩单[考试日期]=$I$4)))),"")} -> 82 | I13: {=IFERROR(AVERAGE(_xlfn.LET(_xlpm.CJ,INDIRECT(_xlfn.CONCAT("表成绩单[",$F$4,"]")),_xlfn._xlws.FILTER(_xlpm.CJ,(表成绩单[班级]=$E13)*(表成绩单[考试日期]=$I$4)))),"")} -> 72.888889 | J13: =IFERROR((表教学质量[[#This Row],[平均分]]-表教学质量[[#Totals],[平均分]])/表教学质量[[#Totals],[平均分]],"") -> 0.0081056362 | K13: {=COUNT(_xlfn.LET(_xlpm.CJ,INDIRECT(_xlfn.CONCAT("表成绩单[",$F$4,"]")),_xlfn._xlws.FILTER(_xlpm.CJ,(表成绩单[班级]=$E13)*(_xlpm.CJ>=$M$4)*(表成绩单[考试日期]=$I$4))))} -> 15 | L13: =表教学质量[[#This Row],[优秀人数]]/表教学质量[[#This Row],[参考人数]] -> 0.33333333 | M13: {=COUNT(_xlfn.LET(_xlpm.CJ,INDIRECT(_xlfn.CONCAT("表成绩单[",$F$4,"]")),_xlfn._xlws.FILTER(_xlpm.CJ,(表成绩单[班级]=$E13)*(_xlpm.CJ>=$N$4)*(表成绩单[考试日期]=$I$4))))} -> 28 | N13: =表教学质量[[#This Row],[良好人数]]/表教学质量[[#This Row],[参考人数]] -> 0.62222222 | O13: {=COUNT(_xlfn.LET(_xlpm.CJ,INDIRECT(_xlfn.CONCAT("表成绩单[",$F$4,"]")),_xlfn._xlws.FILTER(_xlpm.CJ,(表成绩单[班级]=$E13)*(_xlpm.CJ>=$O$4)*(表成绩单[考试日期]=$I$4))))} -> 45 | P13: =表教学质量[[#This Row],[及格人数]]/表教学质量[[#This Row],[参考人数]] -> 1
D14: =ROW()-6 -> 8 | E14: 九年级8班 | F14: 格知班 | G14: {=COUNT(_xlfn.LET(_xlpm.CJ,INDIRECT(_xlfn.CONCAT("表成绩单[",$F$4,"]")),_xlfn._xlws.FILTER(_xlpm.CJ,(表成绩单[班级]=$E14)*(表成绩单[考试日期]=$I$4))))} -> 41 | H14: {=IFERROR(MAX(_xlfn.LET(_xlpm.CJ,INDIRECT(_xlfn.CONCAT("表成绩单[",$F$4,"]")),_xlfn._xlws.FILTER(_xlpm.CJ,(表成绩单[班级]=$E14)*(表成绩单[考试日期]=$I$4)))),"")} -> 82 | I14: {=IFERROR(AVERAGE(_xlfn.LET(_xlpm.CJ,INDIRECT(_xlfn.CONCAT("表成绩单[",$F$4,"]")),_xlfn._xlws.FILTER(_xlpm.CJ,(表成绩单[班级]=$E14)*(表成绩单[考试日期]=$I$4)))),"")} -> 71.609756 | J14: =IFERROR((表教学质量[[#This Row],[平均分]]-表教学质量[[#Totals],[平均分]])/表教学质量[[#Totals],[平均分]],"") -> -0.0095856882 | K14: {=COUNT(_xlfn.LET(_xlpm.CJ,INDIRECT(_xlfn.CONCAT("表成绩单[",$F$4,"]")),_xlfn._xlws.FILTER(_xlpm.CJ,(表成绩单[班级]=$E14)*(_xlpm.CJ>=$M$4)*(表成绩单[考试日期]=$I$4))))} -> 11 | L14: =表教学质量[[#This Row],[优秀人数]]/表教学质量[[#This Row],[参考人数]] -> 0.26829268 | M14: {=COUNT(_xlfn.LET(_xlpm.CJ,INDIRECT(_xlfn.CONCAT("表成绩单[",$F$4,"]")),_xlfn._xlws.FILTER(_xlpm.CJ,(表成绩单[班级]=$E14)*(_xlpm.CJ>=$N$4)*(表成绩单[考试日期]=$I$4))))} -> 27 | N14: =表教学质量[[#This Row],[良好人数]]/表教学质量[[#This Row],[参考人数]] -> 0.65853659 | O14: {=COUNT(_xlfn.LET(_xlpm.CJ,INDIRECT(_xlfn.CONCAT("表成绩单[",$F$4,"]")),_xlfn._xlws.FILTER(_xlpm.CJ,(表成绩单[班级]=$E14)*(_xlpm.CJ>=$O$4)*(表成绩单[考试日期]=$I$4))))} -> 40 | P14: =表教学质量[[#This Row],[及格人数]]/表教学质量[[#This Row],[参考人数]] -> 0.97560976
D15: =ROW()-6 -> 9 | E15: 九年级9班 | F15: 格知班 | G15: {=COUNT(_xlfn.LET(_xlpm.CJ,INDIRECT(_xlfn.CONCAT("表成绩单[",$F$4,"]")),_xlfn._xlws.FILTER(_xlpm.CJ,(表成绩单[班级]=$E15)*(表成绩单[考试日期]=$I$4))))} -> 43 | H15: {=IFERROR(MAX(_xlfn.LET(_xlpm.CJ,INDIRECT(_xlfn.CONCAT("表成绩单[",$F$4,"]")),_xlfn._xlws.FILTER(_xlpm.CJ,(表成绩单[班级]=$E15)*(表成绩单[考试日期]=$I$4)))),"")} -> 84 | I15: {=IFERROR(AVERAGE(_xlfn.LET(_xlpm.CJ,INDIRECT(_xlfn.CONCAT("表成绩单[",$F$4,"]")),_xlfn._xlws.FILTER(_xlpm.CJ,(表成绩单[班级]=$E15)*(表成绩单[考试日期]=$I$4)))),"")} -> 71.674419 | J15: =IFERROR((表教学质量[[#This Row],[平均分]]-表教学质量[[#Totals],[平均分]])/表教学质量[[#Totals],[平均分]],"") -> -0.0086913593 | K15: {=COUNT(_xlfn.LET(_xlpm.CJ,INDIRECT(_xlfn.CONCAT("表成绩单[",$F$4,"]")),_xlfn._xlws.FILTER(_xlpm.CJ,(表成绩单[班级]=$E15)*(_xlpm.CJ>=$M$4)*(表成绩单[考试日期]=$I$4))))} -> 15 | L15: =表教学质量[[#This Row],[优秀人数]]/表教学质量[[#This Row],[参考人数]] -> 0.34883721 | M15: {=COUNT(_xlfn.LET(_xlpm.CJ,INDIRECT(_xlfn.CONCAT("表成绩单[",$F$4,"]")),_xlfn._xlws.FILTER(_xlpm.CJ,(表成绩单[班级]=$E15)*(_xlpm.CJ>=$N$4)*(表成绩单[考试日期]=$I$4))))} -> 22 | N15: =表教学质量[[#This Row],[良好人数]]/表教学质量[[#This Row],[参考人数]] -> 0.51162791 | O15: {=COUNT(_xlfn.LET(_xlpm.CJ,INDIRECT(_xlfn.CONCAT("表成绩单[",$F$4,"]")),_xlfn._xlws.FILTER(_xlpm.CJ,(表成绩单[班级]=$E15)*(_xlpm.CJ>=$O$4)*(表成绩单[考试日期]=$I$4))))} -> 43 | P15: =表教学质量[[#This Row],[及格人数]]/表教学质量[[#This Row],[参考人数]] -> 1
D16: =ROW()-6 -> 10 | E16: 九年级10班 | F16: 格知班 | G16: {=COUNT(_xlfn.LET(_xlpm.CJ,INDIRECT(_xlfn.CONCAT("表成绩单[",$F$4,"]")),_xlfn._xlws.FILTER(_xlpm.CJ,(表成绩单[班级]=$E16)*(表成绩单[考试日期]=$I$4))))} -> 37 | H16: {=IFERROR(MAX(_xlfn.LET(_xlpm.CJ,INDIRECT(_xlfn.CONCAT("表成绩单[",$F$4,"]")),_xlfn._xlws.FILTER(_xlpm.CJ,(表成绩单[班级]=$E16)*(表成绩单[考试日期]=$I$4)))),"")} -> 82 | I16: {=IFERROR(AVERAGE(_xlfn.LET(_xlpm.CJ,INDIRECT(_xlfn.CONCAT("表成绩单[",$F$4,"]")),_xlfn._xlws.FILTER(_xlpm.CJ,(表成绩单[班级]=$E16)*(表成绩单[考试日期]=$I$4)))),"")} -> 74.351351 | J16: =IFERROR((表教学质量[[#This Row],[平均分]]-表教学质量[[#Totals],[平均分]])/表教学质量[[#Totals],[平均分]],"") -> 0.028332541 | K16: {=COUNT(_xlfn.LET(_xlpm.CJ,INDIRECT(_xlfn.CONCAT("表成绩单[",$F$4,"]")),_xlfn._xlws.FILTER(_xlpm.CJ,(表成绩单[班级]=$E16)*(_xlpm.CJ>=$M$4)*(表成绩单[考试日期]=$I$4))))} -> 14 | L16: =表教学质量[[#This Row],[优秀人数]]/表教学质量[[#This Row],[参考人数]] -> 0.37837838 | M16: {=COUNT(_xlfn.LET(_xlpm.CJ,INDIRECT(_xlfn.CONCAT("表成绩单[",$F$4,"]")),_xlfn._xlws.FILTER(_xlpm.CJ,(表成绩单[班级]=$E16)*(_xlpm.CJ>=$N$4)*(表成绩单[考试日期]=$I$4))))} -> 27 | N16: =表教学质量[[#This Row],[良好人数]]/表教学质量[[#This Row],[参考人数]] -> 0.72972973 | O16: {=COUNT(_xlfn.LET(_xlpm.CJ,INDIRECT(_xlfn.CONCAT("表成绩单[",$F$4,"]")),_xlfn._xlws.FILTER(_xlpm.CJ,(表成绩单[班级]=$E16)*(_xlpm.CJ>=$O$4)*(表成绩单[考试日期]=$I$4))))} -> 37 | P16: =表教学质量[[#This Row],[及格人数]]/表教学质量[[#This Row],[参考人数]] -> 1
D17: =ROW()-6 -> 11 | E17: 九年级11班 | F17: 格知班 | G17: {=COUNT(_xlfn.LET(_xlpm.CJ,INDIRECT(_xlfn.CONCAT("表成绩单[",$F$4,"]")),_xlfn._xlws.FILTER(_xlpm.CJ,(表成绩单[班级]=$E17)*(表成绩单[考试日期]=$I$4))))} -> 41 | H17: {=IFERROR(MAX(_xlfn.LET(_xlpm.CJ,INDIRECT(_xlfn.CONCAT("表成绩单[",$F$4,"]")),_xlfn._xlws.FILTER(_xlpm.CJ,(表成绩单[班级]=$E17)*(表成绩单[考试日期]=$I$4)))),"")} -> 88 | I17: {=IFERROR(AVERAGE(_xlfn.LET(_xlpm.CJ,INDIRECT(_xlfn.CONCAT("表成绩单[",$F$4,"]")),_xlfn._xlws.FILTER(_xlpm.CJ,(表成绩单[班级]=$E17)*(表成绩单[考试日期]=$I$4)))),"")} -> 73.195122 | J17: =IFERROR((表教学质量[[#This Row],[平均分]]-表教学质量[[#Totals],[平均分]])/表教学质量[[#Totals],[平均分]],"") -> 0.012341059 | K17: {=COUNT(_xlfn.LET(_xlpm.CJ,INDIRECT(_xlfn.CONCAT("表成绩单[",$F$4,"]")),_xlfn._xlws.FILTER(_xlpm.CJ,(表成绩单[班级]=$E17)*(_xlpm.CJ>=$M$4)*(表成绩单[考试日期]=$I$4))))} -> 16 | L17: =表教学质量[[#This Row],[优秀人数]]/表教学质量[[#This Row],[参考人数]] -> 0.3902439 | M17: {=COUNT(_xlfn.LET(_xlpm.CJ,INDIRECT(_xlfn.CONCAT("表成绩单[",$F$4,"]")),_xlfn._xlws.FILTER(_xlpm.CJ,(表成绩单[班级]=$E17)*(_xlpm.CJ>=$N$4)*(表成绩单[考试日期]=$I$4))))} -> 28 | N17: =表教学质量[[#This Row],[良好人数]]/表教学质量[[#This Row],[参考人数]] -> 0.68292683 | O17: {=COUNT(_xlfn.LET(_xlpm.CJ,INDIRECT(_xlfn.CONCAT("表成绩单[",$F$4,"]")),_xlfn._xlws.FILTER(_xlpm.CJ,(表成绩单[班级]=$E17)*(_xlpm.CJ>=$O$4)*(表成绩单[考试日期]=$I$4))))} -> 40 | P17: =表教学质量[[#This Row],[及格人数]]/表教学质量[[#This Row],[参考人数]] -> 0.97560976
D18: =ROW()-6 -> 12 | E18: 九年级12班 | F18: 南山班 | G18: {=COUNT(_xlfn.LET(_xlpm.CJ,INDIRECT(_xlfn.CONCAT("表成绩单[",$F$4,"]")),_xlfn._xlws.FILTER(_xlpm.CJ,(表成绩单[班级]=$E18)*(表成绩单[考试日期]=$I$4))))} -> 40 | H18: {=IFERROR(MAX(_xlfn.LET(_xlpm.CJ,INDIRECT(_xlfn.CONCAT("表成绩单[",$F$4,"]")),_xlfn._xlws.FILTER(_xlpm.CJ,(表成绩单[班级]=$E18)*(表成绩单[考试日期]=$I$4)))),"")} -> 85 | I18: {=IFERROR(AVERAGE(_xlfn.LET(_xlpm.CJ,INDIRECT(_xlfn.CONCAT("表成绩单[",$F$4,"]")),_xlfn._xlws.FILTER(_xlpm.CJ,(表成绩单[班级]=$E18)*(表成绩单[考试日期]=$I$4)))),"")} -> 74.825 | J18: =IFERROR((表教学质量[[#This Row],[平均分]]-表教学质量[[#Totals],[平均分]])/表教学质量[[#Totals],[平均分]],"") -> 0.034883442 | K18: {=COUNT(_xlfn.LET(_xlpm.CJ,INDIRECT(_xlfn.CONCAT("表成绩单[",$F$4,"]")),_xlfn._xlws.FILTER(_xlpm.CJ,(表成绩单[班级]=$E18)*(_xlpm.CJ>=$M$4)*(表成绩单[考试日期]=$I$4))))} -> 14 | L18: =表教学质量[[#This Row],[优秀人数]]/表教学质量[[#This Row],[参考人数]] -> 0.35 | M18: {=COUNT(_xlfn.LET(_xlpm.CJ,INDIRECT(_xlfn.CONCAT("表成绩单[",$F$4,"]")),_xlfn._xlws.FILTER(_xlpm.CJ,(表成绩单[班级]=$E18)*(_xlpm.CJ>=$N$4)*(表成绩单[考试日期]=$I$4))))} -> 30 | N18: =表教学质量[[#This Row],[良好人数]]/表教学质量[[#This Row],[参考人数]] -> 0.75 | O18: {=COUNT(_xlfn.LET(_xlpm.CJ,INDIRECT(_xlfn.CONCAT("表成绩单[",$F$4,"]")),_xlfn._xlws.FILTER(_xlpm.CJ,(表成绩单[班级]=$E18)*(_xlpm.CJ>=$O$4)*(表成绩单[考试日期]=$I$4))))} -> 40 | P18: =表教学质量[[#This Row],[及格人数]]/表教学质量[[#This Row],[参考人数]] -> 1
... D25: =ROW()-6 -> 19 | E25: 九年级19班 | F25: 南山班 | G25: {=COUNT(_xlfn.LET(_xlpm.CJ,INDIRECT(_xlfn.CONCAT("表成绩单[",$F$4,"]")),_xlfn._xlws.FILTER(_xlpm.CJ,(表成绩单[班级]=$E25)*(表成绩单[考试日期]=$I$4))))} -> 42 | H25: {=IFERROR(MAX(_xlfn.LET(_xlpm.CJ,INDIRECT(_xlfn.CONCAT("表成绩单[",$F$4,"]")),_xlfn._xlws.FILTER(_xlpm.CJ,(表成绩单[班级]=$E25)*(表成绩单[考试日期]=$I$4)))),"")} -> 85 | I25: {=IFERROR(AVERAGE(_xlfn.LET(_xlpm.CJ,INDIRECT(_xlfn.CONCAT("表成绩单[",$F$4,"]")),_xlfn._xlws.FILTER(_xlpm.CJ,(表成绩单[班级]=$E25)*(表成绩单[考试日期]=$I$4)))),"")} -> 77.071429 | J25: =IFERROR((表教学质量[[#This Row],[平均分]]-表教学质量[[#Totals],[平均分]])/表教学质量[[#Totals],[平均分]],"") -> 0.065953161 | K25: {=COUNT(_xlfn.LET(_xlpm.CJ,INDIRECT(_xlfn.CONCAT("表成绩单[",$F$4,"]")),_xlfn._xlws.FILTER(_xlpm.CJ,(表成绩单[班级]=$E25)*(_xlpm.CJ>=$M$4)*(表成绩单[考试日期]=$I$4))))} -> 27 | L25: =表教学质量[[#This Row],[优秀人数]]/表教学质量[[#This Row],[参考人数]] -> 0.64285714 | M25: {=COUNT(_xlfn.LET(_xlpm.CJ,INDIRECT(_xlfn.CONCAT("表成绩单[",$F$4,"]")),_xlfn._xlws.FILTER(_xlpm.CJ,(表成绩单[班级]=$E25)*(_xlpm.CJ>=$N$4)*(表成绩单[考试日期]=$I$4))))} -> 37 | N25: =表教学质量[[#This Row],[良好人数]]/表教学质量[[#This Row],[参考人数]] -> 0.88095238 | O25: {=COUNT(_xlfn.LET(_xlpm.CJ,INDIRECT(_xlfn.CONCAT("表成绩单[",$F$4,"]")),_xlfn._xlws.FILTER(_xlpm.CJ,(表成绩单[班级]=$E25)*(_xlpm.CJ>=$O$4)*(表成绩单[考试日期]=$I$4))))} -> 42 | P25: =表教学质量[[#This Row],[及格人数]]/表教学质量[[#This Row],[参考人数]] -> 1
D26: 汇总 | E26: =SUBTOTAL(103,表教学质量[班级]) -> 19 | G26: =SUBTOTAL(109,表教学质量[参考人数]) -> 783 | H26: =SUBTOTAL(104,表教学质量[最高分]) -> 88 | I26: =SUBTOTAL(101,表教学质量[平均分]) -> 72.302828 | J26: =_xlfn.STDEV.S(INDIRECT(_xlfn.CONCAT("表成绩单[",$F$4,"]"))) -> 12.461859 | K26: =SUBTOTAL(109,表教学质量[优秀人数]) -> 290 | L26: =表教学质量[[#Totals],[优秀人数]]/表教学质量[[#Totals],[参考人数]] -> 0.37037037 | M26: =SUBTOTAL(109,表教学质量[良好人数]) -> 512 | N26: =表教学质量[[#Totals],[良好人数]]/表教学质量[[#Totals],[参考人数]] -> 0.65389527 | O26: =SUBTOTAL(109,表教学质量[及格人数]) -> 750 | P26: =表教学质量[[#Totals],[及格人数]]/表教学质量[[#Totals],[参考人数]] -> 0.95785441

Sheet 成绩单汇总
D2: 成绩单汇总（九年级） | V2: 密码： | W2: 123
D4: 考试日期 | E4: 准考证号 | F4: 班级 | G4: 姓名 | H4: 语文 | I4: 数学 | J4: 英语 | K4: 物理 | L4: 化学 | M4: 政治 | N4: 历史 | O4: 总分 | P4: 语文校排 | Q4: 数学校排 | R4: 英语校排 | S4: 物理校排 | T4: 化学校排 | U4: 政治校排 | V4: 历史校排 | W4: 总分校排
D5: 45975 | E5: 19176896 | F5: 九年级15班 | G5: 张艺菱 | H5: 114 | I5: 119 | J5: 89 | K5: 88 | L5: 86 | M5: 84 | N5: 79 | O5: 659 | P5: {=IF(表成绩单[[#This Row],[语文]]="","",SUMPRODUCT((表成绩单[考试日期]=表成绩单[[#This Row],[考试日期]])*(表成绩单[语文]<9E+307)*(表成绩单[语文]>表成绩单[[#This Row],[语文]]))+1)} -> 4 | Q5: {=IF(表成绩单[[#This Row],[数学]]="","",SUMPRODUCT((表成绩单[考试日期]=表成绩单[[#This Row],[考试日期]])*(表成绩单[数学]<9E+307)*(表成绩单[数学]>表成绩单[[#This Row],[数学]]))+1)} -> 11 | R5: {=IF(表成绩单[[#This Row],[英语]]="","",SUMPRODUCT((表成绩单[考试日期]=表成绩单[[#This Row],[考试日期]])*(表成绩单[英语]<9E+307)*(表成绩单[英语]>表成绩单[[#This Row],[英语]]))+1)} -> 1 | S5: {=IF(表成绩单[[#This Row],[物理]]="","",SUMPRODUCT((表成绩单[考试日期]=表成绩单[[#This Row],[考试日期]])*(表成绩单[物理]<9E+307)*(表成绩单[物理]>表成绩单[[#This Row],[物理]]))+1)} -> 54 | T5: {=IF(表成绩单[[#This Row],[化学]]="","",SUMPRODUCT((表成绩单[考试日期]=表成绩单[[#This Row],[考试日期]])*(表成绩单[化学]<9E+307)*(表成绩单[化学]>表成绩单[[#This Row],[化学]]))+1)} -> 8 | U5: {=IF(表成绩单[[#This Row],[政治]]="","",SUMPRODUCT((表成绩单[考试日期]=表成绩单[[#This Row],[考试日期]])*(表成绩单[政治]<9E+307)*(表成绩单[政治]>表成绩单[[#This Row],[政治]]))+1)} -> 83 | V5: {=IF(表成绩单[[#This Row],[历史]]="","",SUMPRODUCT((表成绩单[考试日期]=表成绩单[[#This Row],[考试日期]])*(表成绩单[历史]<9E+307)*(表成绩单[历史]>表成绩单[[#This Row],[历史]]))+1)} -> 144 | W5: {=IF(表成绩单[[#This Row],[总分]]="","",SUMPRODUCT((表成绩单[考试日期]=表成绩单[[#This Row],[考试日期]])*(表成绩单[总分]<9E+307)*(表成绩单[总分]>表成绩单[[#This Row],[总分]]))+1)} -> 1
D6: 45975 | E6: 19173522 | F6: 九年级19班 | G6: 刘彧恺 | H6: 106 | I6: 118 | J6: 89 | K6: 87 | L6: 86 | M6: 87 | N6: 84 | O6: 657 | P6: {=IF(表成绩单[[#This Row],[语文]]="","",SUMPRODUCT((表成绩单[考试日期]=表成绩单[[#This Row],[考试日期]])*(表成绩单[语文]<9E+307)*(表成绩单[语文]>表成绩单[[#This Row],[语文]]))+1)} -> 62 | Q6: {=IF(表成绩单[[#This Row],[数学]]="","",SUMPRODUCT((表成绩单[考试日期]=表成绩单[[#This Row],[考试日期]])*(表成绩单[数学]<9E+307)*(表成绩单[数学]>表成绩单[[#This Row],[数学]]))+1)} -> 22 | R6: {=IF(表成绩单[[#This Row],[英语]]="","",SUMPRODUCT((表成绩单[考试日期]=表成绩单[[#This Row],[考试日期]])*(表成绩单[英语]<9E+307)*(表成绩单[英语]>表成绩单[[#This Row],[英语]]))+1)} -> 1 | S6: {=IF(表成绩单[[#This Row],[物理]]="","",SUMPRODUCT((表成绩单[考试日期]=表成绩单[[#This Row],[考试日期]])*(表成绩单[物理]<9E+307)*(表成绩单[物理]>表成绩单[[#This Row],[物理]]))+1)} -> 127 | T6: {=IF(表成绩单[[#This Row],[化学]]="","",SUMPRODUCT((表成绩单[考试日期]=表成绩单[[#This Row],[考试日期]])*(表成绩单[化学]<9E+307)*(表成绩单[化学]>表成绩单[[#This Row],[化学]]))+1)} -> 8 | U6: {=IF(表成绩单[[#This Row],[政治]]="","",SUMPRODUCT((表成绩单[考试日期]=表成绩单[[#This Row],[考试日期]])*(表成绩单[政治]<9E+307)*(表成绩单[政治]>表成绩单[[#This Row],[政治]]))+1)} -> 13 | V6: {=IF(表成绩单[[#This Row],[历史]]="","",SUMPRODUCT((表成绩单[考试日期]=表成绩单[[#This Row],[考试日期]])*(表成绩单[历史]<9E+307)*(表成绩单[历史]>表成绩单[[#This Row],[历史]]))+1)} -> 8 | W6: {=IF(表成绩单[[#This Row],[总分]]="","",SUMPRODUCT((表成绩单[考试日期]=表成绩单[[#This Row],[考试日期]])*(表成绩单[总分]<9E+307)*(表成绩单[总分]>表成绩单[[#This Row],[总分]]))+1)} -> 2
D7: 45975 | E7: 19176875 | F7: 九年级15班 | G7: 梁雅文 | H7: 109 | I7: 117 | J7: 86 | K7: 88 | L7: 79 | M7: 88 | N7: 86 | O7: 653 | P7: {=IF(表成绩单[[#This Row],[语文]]="","",SUMPRODUCT((表成绩单[考试日期]=表成绩单[[#This Row],[考试日期]])*(表成绩单[语文]<9E+307)*(表成绩单[语文]>表成绩单[[#This Row],[语文]]))+1)} -> 18 | Q7: {=IF(表成绩单[[#This Row],[数学]]="","",SUMPRODUCT((表成绩单[考试日期]=表成绩单[[#This Row],[考试日期]])*(表成绩单[数学]<9E+307)*(表成绩单[数学]>表成绩单[[#This Row],[数学]]))+1)} -> 37 | R7: {=IF(表成绩单[[#This Row],[英语]]="","",SUMPRODUCT((表成绩单[考试日期]=表成绩单[[#This Row],[考试日期]])*(表成绩单[英语]<9E+307)*(表成绩单[英语]>表成绩单[[#This Row],[英语]]))+1)} -> 42 | S7: {=IF(表成绩单[[#This Row],[物理]]="","",SUMPRODUCT((表成绩单[考试日期]=表成绩单[[#This Row],[考试日期]])*(表成绩单[物理]<9E+307)*(表成绩单[物理]>表成绩单[[#This Row],[物理]]))+1)} -> 54 | T7: {=IF(表成绩单[[#This Row],[化学]]="","",SUMPRODUCT((表成绩单[考试日期]=表成绩单[[#This Row],[考试日期]])*(表成绩单[化学]<9E+307)*(表成绩单[化学]>表成绩单[[#This Row],[化学]]))+1)} -> 166 | U7: {=IF(表成绩单[[#This Row],[政治]]="","",SUMPRODUCT((表成绩单[考试日期]=表成绩单[[#This Row],[考试日期]])*(表成绩单[政治]<9E+307)*(表成绩单[政治]>表成绩单[[#This Row],[政治]]))+1)} -> 4 | V7: {=IF(表成绩单[[#This Row],[历史]]="","",SUMPRODUCT((表成绩单[考试日期]=表成绩单[[#This Row],[考试日期]])*(表成绩单[历史]<9E+307)*(表成绩单[历史]>表成绩单[[#This Row],[历史]]))+1)} -> 1 | W7: {=IF(表成绩单[[#This Row],[总分]]="","",SUMPRODUCT((表成绩单[考试日期]=表成绩单[[#This Row],[考试日期]])*(表成绩单[总分]<9E+307)*(表成绩单[总分]>表成绩单[[#This Row],[总分]]))+1)} -> 3
D8: 45975 | E8: 19174435 | F8: 九年级17班 | G8: 丁启亮 | H8: 106 | I8: 120 | J8: 89 | K8: 86 | L8: 86 | M8: 83 | N8: 82 | O8: 652 | P8: {=IF(表成绩单[[#This Row],[语文]]="","",SUMPRODUCT((表成绩单[考试日期]=表成绩单[[#This Row],[考试日期]])*(表成绩单[语文]<9E+307)*(表成绩单[语文]>表成绩单[[#This Row],[语文]]))+1)} -> 62 | Q8: {=IF(表成绩单[[#This Row],[数学]]="","",SUMPRODUCT((表成绩单[考试日期]=表成绩单[[#This Row],[考试日期]])*(表成绩单[数学]<9E+307)*(表成绩单[数学]>表成绩单[[#This Row],[数学]]))+1)} -> 1 | R8: {=IF(表成绩单[[#This Row],[英语]]="","",SUMPRODUCT((表成绩单[考试日期]=表成绩单[[#This Row],[考试日期]])*(表成绩单[英语]<9E+307)*(表成绩单[英语]>表成绩单[[#This Row],[英语]]))+1)} -> 1 | S8: {=IF(表成绩单[[#This Row],[物理]]="","",SUMPRODUCT((表成绩单[考试日期]=表成绩单[[#This Row],[考试日期]])*(表成绩单[物理]<9E+307)*(表成绩单[物理]>表成绩单[[#This Row],[物理]]))+1)} -> 187 | T8: {=IF(表成绩单[[#This Row],[化学]]="","",SUMPRODUCT((表成绩单[考试日期]=表成绩单[[#This Row],[考试日期]])*(表成绩单[化学]<9E+307)*(表成绩单[化学]>表成绩单[[#This Row],[化学]]))+1)} -> 8 | U8: {=IF(表成绩单[[#This Row],[政治]]="","",SUMPRODUCT((表成绩单[考试日期]=表成绩单[[#This Row],[考试日期]])*(表成绩单[政治]<9E+307)*(表成绩单[政治]>表成绩单[[#This Row],[政治]]))+1)} -> 121 | V8: {=IF(表成绩单[[#This Row],[历史]]="","",SUMPRODUCT((表成绩单[考试日期]=表成绩单[[#This Row],[考试日期]])*(表成绩单[历史]<9E+307)*(表成绩单[历史]>表成绩单[[#This Row],[历史]]))+1)} -> 35 | W8: {=IF(表成绩单[[#This Row],[总分]]="","",SUMPRODUCT((表成绩单[考试日期]=表成绩单[[#This Row],[考试日期]])*(表成绩单[总分]<9E+307)*(表成绩单[总分]>表成绩单[[#This Row],[总分]]))+1)} -> 4
D9: 45975 | E9: 19177203 | F9: 九年级14班 | G9: 何柏恒 | H9: 107 | I9: 118 | J9: 87 | K9: 90 | L9: 84 | M9: 84 | N9: 82 | O9: 652 | P9: {=IF(表成绩单[[#This Row],[语文]]="","",SUMPRODUCT((表成绩单[考试日期]=表成绩单[[#This Row],[考试日期]])*(表成绩单[语文]<9E+307)*(表成绩单[语文]>表成绩单[[#This Row],[语文]]))+1)} -> 45 | Q9: {=IF(表成绩单[[#This Row],[数学]]="","",SUMPRODUCT((表成绩单[考试日期]=表成绩单[[#This Row],[考试日期]])*(表成绩单[数学]<9E+307)*(表成绩单[数学]>表成绩单[[#This Row],[数学]]))+1)} -> 22 | R9: {=IF(表成绩单[[#This Row],[英语]]="","",SUMPRODUCT((表成绩单[考试日期]=表成绩单[[#This Row],[考试日期]])*(表成绩单[英语]<9E+307)*(表成绩单[英语]>表成绩单[[#This Row],[英语]]))+1)} -> 20 | S9: {=IF(表成绩单[[#This Row],[物理]]="","",SUMPRODUCT((表成绩单[考试日期]=表成绩单[[#This Row],[考试日期]])*(表成绩单[物理]<9E+307)*(表成绩单[物理]>表成绩单[[#This Row],[物理]]))+1)} -> 1 | T9: {=IF(表成绩单[[#This Row],[化学]]="","",SUMPRODUCT((表成绩单[考试日期]=表成绩单[[#This Row],[考试日期]])*(表成绩单[化学]<9E+307)*(表成绩单[化学]>表成绩单[[#This Row],[化学]]))+1)} -> 33 | U9: {=IF(表成绩单[[#This Row],[政治]]="","",SUMPRODUCT((表成绩单[考试日期]=表成绩单[[#This Row],[考试日期]])*(表成绩单[政治]<9E+307)*(表成绩单[政治]>表成绩单[[#This Row],[政治]]))+1)} -> 83 | V9: {=IF(表成绩单[[#This Row],[历史]]="","",SUMPRODUCT((表成绩单[考试日期]=表成绩单[[#This Row],[考试日期]])*(表成绩单[历史]<9E+307)*(表成绩单[历史]>表成绩单[[#This Row],[历史]]))+1)} -> 35 | W9: {=IF(表成绩单[[#This Row],[总分]]="","",SUMPRODUCT((表成绩单[考试日期]=表成绩单[[#This Row],[考试日期]])*(表成绩单[总分]<9E+307)*(表成绩单[总分]>表成绩单[[#This Row],[总分]]))+1)} -> 4
D10: 45975 | E10: 19175400 | F10: 九年级18班 | G10: 刘颖珊 | H10: 112 | I10: 116 | J10: 89 | K10: 86 | L10: 85 | M10: 80 | N10: 82 | O10: 650 | P10: {=IF(表成绩单[[#This Row],[语文]]="","",SUMPRODUCT((表成绩单[考试日期]=表成绩单[[#This Row],[考试日期]])*(表成绩单[语文]<9E+307)*(表成绩单[语文]>表成绩单[[#This Row],[语文]]))+1)} -> 7 | Q10: {=IF(表成绩单[[#This Row],[数学]]="","",SUMPRODUCT((表成绩单[考试日期]=表成绩单[[#This Row],[考试日期]])*(表成绩单[数学]<9E+307)*(表成绩单[数学]>表成绩单[[#This Row],[数学]]))+1)} -> 50 | R10: {=IF(表成绩单[[#This Row],[英语]]="","",SUMPRODUCT((表成绩单[考试日期]=表成绩单[[#This Row],[考试日期]])*(表成绩单[英语]<9E+307)*(表成绩单[英语]>表成绩单[[#This Row],[英语]]))+1)} -> 1 | S10: {=IF(表成绩单[[#This Row],[物理]]="","",SUMPRODUCT((表成绩单[考试日期]=表成绩单[[#This Row],[考试日期]])*(表成绩单[物理]<9E+307)*(表成绩单[物理]>表成绩单[[#This Row],[物理]]))+1)} -> 187 | T10: {=IF(表成绩单[[#This Row],[化学]]="","",SUMPRODUCT((表成绩单[考试日期]=表成绩单[[#This Row],[考试日期]])*(表成绩单[化学]<9E+307)*(表成绩单[化学]>表成绩单[[#This Row],[化学]]))+1)} -> 19 | U10: {=IF(表成绩单[[#This Row],[政治]]="","",SUMPRODUCT((表成绩单[考试日期]=表成绩单[[#This Row],[考试日期]])*(表成绩单[政治]<9E+307)*(表成绩单[政治]>表成绩单[[#This Row],[政治]]))+1)} -> 209 | V10: {=IF(表成绩单[[#This Row],[历史]]="","",SUMPRODUCT((表成绩单[考试日期]=表成绩单[[#This Row],[考试日期]])*(表成绩单[历史]<9E+307)*(表成绩单[历史]>表成绩单[[#This Row],[历史]]))+1)} -> 35 | W10: {=IF(表成绩单[[#This Row],[总分]]="","",SUMPRODUCT((表成绩单[考试日期]=表成绩单[[#This Row],[考试日期]])*(表成绩单[总分]<9E+307)*(表成绩单[总分]>表成绩单[[#This Row],[总分]]))+1)} -> 6
D11: 45975 | E11: 19176883 | F11: 九年级15班 | G11: 罗茵潆 | H11: 110 | I11: 117 | J11: 87 | K11: 90 | L11: 74 | M11: 87 | N11: 85 | O11: 650 | P11: {=IF(表成绩单[[#This Row],[语文]]="","",SUMPRODUCT((表成绩单[考试日期]=表成绩单[[#This Row],[考试日期]])*(表成绩单[语文]<9E+307)*(表成绩单[语文]>表成绩单[[#This Row],[语文]]))+1)} -> 13 | Q11: {=IF(表成绩单[[#This Row],[数学]]="","",SUMPRODUCT((表成绩单[考试日期]=表成绩单[[#This Row],[考试日期]])*(表成绩单[数学]<9E+307)*(表成绩单[数学]>表成绩单[[#This Row],[数学]]))+1)} -> 37 | R11: {=IF(表成绩单[[#This Row],[英语]]="","",SUMPRODUCT((表成绩单[考试日期]=表成绩单[[#This Row],[考试日期]])*(表成绩单[英语]<9E+307)*(表成绩单[英语]>表成绩单[[#This Row],[英语]]))+1)} -> 20 | S11: {=IF(表成绩单[[#This Row],[物理]]="","",SUMPRODUCT((表成绩单[考试日期]=表成绩单[[#This Row],[考试日期]])*(表成绩单[物理]<9E+307)*(表成绩单[物理]>表成绩单[[#This Row],[物理]]))+1)} -> 1 | T11: {=IF(表成绩单[[#This Row],[化学]]="","",SUMPRODUCT((表成绩单[考试日期]=表成绩单[[#This Row],[考试日期]])*(表成绩单[化学]<9E+307)*(表成绩单[化学]>表成绩单[[#This Row],[化学]]))+1)} -> 337 | U11: {=IF(表成绩单[[#This Row],[政治]]="","",SUMPRODUCT((表成绩单[考试日期]=表成绩单[[#This Row],[考试日期]])*(表成绩单[政治]<9E+307)*(表成绩单[政治]>表成绩单[[#This Row],[政治]]))+1)} -> 13 | V11: {=IF(表成绩单[[#This Row],[历史]]="","",SUMPRODUCT((表成绩单[考试日期]=表成绩单[[#This Row],[考试日期]])*(表成绩单[历史]<9E+307)*(表成绩单[历史]>表成绩单[[#This Row],[历史]]))+1)} -> 3 | W11: {=IF(表成绩单[[#This Row],[总分]]="","",SUMPRODUCT((表成绩单[考试日期]=表成绩单[[#This Row],[考试日期]])*(表成绩单[总分]<9E+307)*(表成绩单[总分]>表成绩单[[#This Row],[总分]]))+1)} -> 6
D12: 45975 | E12: 19174789 | F12: 九年级13班 | G12: 骆煜祺 | H12: 105 | I12: 116 | J12: 82 | K12: 88 | L12: 86 | M12: 86 | N12: 84 | O12: 647 | P12: {=IF(表成绩单[[#This Row],[语文]]="","",SUMPRODUCT((表成绩单[考试日期]=表成绩单[[#This Row],[考试日期]])*(表成绩单[语文]<9E+307)*(表成绩单[语文]>表成绩单[[#This Row],[语文]]))+1)} -> 80 | Q12: {=IF(表成绩单[[#This Row],[数学]]="","",SUMPRODUCT((表成绩单[考试日期]=表成绩单[[#This Row],[考试日期]])*(表成绩单[数学]<9E+307)*(表成绩单[数学]>表成绩单[[#This Row],[数学]]))+1)} -> 50 | R12: {=IF(表成绩单[[#This Row],[英语]]="","",SUMPRODUCT((表成绩单[考试日期]=表成绩单[[#This Row],[考试日期]])*(表成绩单[英语]<9E+307)*(表成绩单[英语]>表成绩单[[#This Row],[英语]]))+1)} -> 195 | S12: {=IF(表成绩单[[#This Row],[物理]]="","",SUMPRODUCT((表成绩单[考试日期]=表成绩单[[#This Row],[考试日期]])*(表成绩单[物理]<9E+307)*(表成绩单[物理]>表成绩单[[#This Row],[物理]]))+1)} -> 54 | T12: {=IF(表成绩单[[#This Row],[化学]]="","",SUMPRODUCT((表成绩单[考试日期]=表成绩单[[#This Row],[考试日期]])*(表成绩单[化学]<9E+307)*(表成绩单[化学]>表成绩单[[#This Row],[化学]]))+1)} -> 8 | U12: {=IF(表成绩单[[#This Row],[政治]]="","",SUMPRODUCT((表成绩单[考试日期]=表成绩单[[#This Row],[考试日期]])*(表成绩单[政治]<9E+307)*(表成绩单[政治]>表成绩单[[#This Row],[政治]]))+1)} -> 26 | V12: {=IF(表成绩单[[#This Row],[历史]]="","",SUMPRODUCT((表成绩单[考试日期]=表成绩单[[#This Row],[考试日期]])*(表成绩单[历史]<9E+307)*(表成绩单[历史]>表成绩单[[#This Row],[历史]]))+1)} -> 8 | W12: {=IF(表成绩单[[#This Row],[总分]]="","",SUMPRODUCT((表成绩单[考试日期]=表成绩单[[#This Row],[考试日期]])*(表成绩单[总分]<9E+307)*(表成绩单[总分]>表成绩单[[#This Row],[总分]]))+1)} -> 8
D13: 45975 | E13: 19176874 | F13: 九年级15班 | G13: 李知与 | H13: 113 | I13: 107 | J13: 88 | K13: 88 | L13: 82 | M13: 85 | N13: 84 | O13: 647 | P13: {=IF(表成绩单[[#This Row],[语文]]="","",SUMPRODUCT((表成绩单[考试日期]=表成绩单[[#This Row],[考试日期]])*(表成绩单[语文]<9E+307)*(表成绩单[语文]>表成绩单[[#This Row],[语文]]))+1)} -> 5 | Q13: {=IF(表成绩单[[#This Row],[数学]]="","",SUMPRODUCT((表成绩单[考试日期]=表成绩单[[#This Row],[考试日期]])*(表成绩单[数学]<9E+307)*(表成绩单[数学]>表成绩单[[#This Row],[数学]]))+1)} -> 200 | R13: {=IF(表成绩单[[#This Row],[英语]]="","",SUMPRODUCT((表成绩单[考试日期]=表成绩单[[#This Row],[考试日期]])*(表成绩单[英语]<9E+307)*(表成绩单[英语]>表成绩单[[#This Row],[英语]]))+1)} -> 10 | S13: {=IF(表成绩单[[#This Row],[物理]]="","",SUMPRODUCT((表成绩单[考试日期]=表成绩单[[#This Row],[考试日期]])*(表成绩单[物理]<9E+307)*(表成绩单[物理]>表成绩单[[#This Row],[物理]]))+1)} -> 54 | T13: {=IF(表成绩单[[#This Row],[化学]]="","",SUMPRODUCT((表成绩单[考试日期]=表成绩单[[#This Row],[考试日期]])*(表成绩单[化学]<9E+307)*(表成绩单[化学]>表成绩单[[#This Row],[化学]]))+1)} -> 71 | U13: {=IF(表成绩单[[#This Row],[政治]]="","",SUMPRODUCT((表成绩单[考试日期]=表成绩单[[#This Row],[考试日期]])*(表成绩单[政治]<9E+307)*(表成绩单[政治]>表成绩单[[#This Row],[政治]]))+1)} -> 45 | V13: {=IF(表成绩单[[#This Row],[历史]]="","",SUMPRODUCT((表成绩单[考试日期]=表成绩单[[#This Row],[考试日期]])*(表成绩单[历史]<9E+307)*(表成绩单[历史]>表成绩单[[#This Row],[历史]]))+1)} -> 8 | W13: {=IF(表成绩单[[#This Row],[总分]]="","",SUMPRODUCT((表成绩单[考试日期]=表成绩单[[#This Row],[考试日期]])*(表成绩单[总分]<9E+307)*(表成绩单[总分]>表成绩单[[#This Row],[总分]]))+1)} -> 8
D14: 45975 | E14: 19167643 | F14: 九年级19班 | G14: 冯俊玮 | H14: 105 | I14: 113 | J14: 87 | K14: 89 | L14: 85 | M14: 86 | N14: 81 | O14: 646 | P14: {=IF(表成绩单[[#This Row],[语文]]="","",SUMPRODUCT((表成绩单[考试日期]=表成绩单[[#This Row],[考试日期]])*(表成绩单[语文]<9E+307)*(表成绩单[语文]>表成绩单[[#This Row],[语文]]))+1)} -> 80 | Q14: {=IF(表成绩单[[#This Row],[数学]]="","",SUMPRODUCT((表成绩单[考试日期]=表成绩单[[#This Row],[考试日期]])*(表成绩单[数学]<9E+307)*(表成绩单[数学]>表成绩单[[#This Row],[数学]]))+1)} -> 93 | R14: {=IF(表成绩单[[#This Row],[英语]]="","",SUMPRODUCT((表成绩单[考试日期]=表成绩单[[#This Row],[考试日期]])*(表成绩单[英语]<9E+307)*(表成绩单[英语]>表成绩单[[#This Row],[英语]]))+1)} -> 20 | S14: {=IF(表成绩单[[#This Row],[物理]]="","",SUMPRODUCT((表成绩单[考试日期]=表成绩单[[#This Row],[考试日期]])*(表成绩单[物理]<9E+307)*(表成绩单[物理]>表成绩单[[#This Row],[物理]]))+1)} -> 18 | T14: {=IF(表成绩单[[#This Row],[化学]]="","",SUMPRODUCT((表成绩单[考试日期]=表成绩单[[#This Row],[考试日期]])*(表成绩单[化学]<9E+307)*(表成绩单[化学]>表成绩单[[#This Row],[化学]]))+1)} -> 19 | U14: {=IF(表成绩单[[#This Row],[政治]]="","",SUMPRODUCT((表成绩单[考试日期]=表成绩单[[#This Row],[考试日期]])*(表成绩单[政治]<9E+307)*(表成绩单[政治]>表成绩单[[#This Row],[政治]]))+1)} -> 26 | V14: {=IF(表成绩单[[#This Row],[历史]]="","",SUMPRODUCT((表成绩单[考试日期]=表成绩单[[#This Row],[考试日期]])*(表成绩单[历史]<9E+307)*(表成绩单[历史]>表成绩单[[#This Row],[历史]]))+1)} -> 63 | W14: {=IF(表成绩单[[#This Row],[总分]]="","",SUMPRODUCT((表成绩单[考试日期]=表成绩单[[#This Row],[考试日期]])*(表成绩单[总分]<9E+307)*(表成绩单[总分]>表成绩单[[#This Row],[总分]]))+1)} -> 10
D15: 45975 | E15: 19167652 | F15: 九年级19班 | G15: 江志远 | H15: 106 | I15: 115 | J15: 88 | K15: 88 | L15: 81 | M15: 85 | N15: 83 | O15: 646 | P15: {=IF(表成绩单[[#This Row],[语文]]="","",SUMPRODUCT((表成绩单[考试日期]=表成绩单[[#This Row],[考试日期]])*(表成绩单[语文]<9E+307)*(表成绩单[语文]>表成绩单[[#This Row],[语文]]))+1)} -> 62 | Q15: {=IF(表成绩单[[#This Row],[数学]]="","",SUMPRODUCT((表成绩单[考试日期]=表成绩单[[#This Row],[考试日期]])*(表成绩单[数学]<9E+307)*(表成绩单[数学]>表成绩单[[#This Row],[数学]]))+1)} -> 63 | R15: {=IF(表成绩单[[#This Row],[英语]]="","",SUMPRODUCT((表成绩单[考试日期]=表成绩单[[#This Row],[考试日期]])*(表成绩单[英语]<9E+307)*(表成绩单[英语]>表成绩单[[#This Row],[英语]]))+1)} -> 10 | S15: {=IF(表成绩单[[#This Row],[物理]]="","",SUMPRODUCT((表成绩单[考试日期]=表成绩单[[#This Row],[考试日期]])*(表成绩单[物理]<9E+307)*(表成绩单[物理]>表成绩单[[#This Row],[物理]]))+1)} -> 54 | T15: {=IF(表成绩单[[#This Row],[化学]]="","",SUMPRODUCT((表成绩单[考试日期]=表成绩单[[#This Row],[考试日期]])*(表成绩单[化学]<9E+307)*(表成绩单[化学]>表成绩单[[#This Row],[化学]]))+1)} -> 100 | U15: {=IF(表成绩单[[#This Row],[政治]]="","",SUMPRODUCT((表成绩单[考试日期]=表成绩单[[#This Row],[考试日期]])*(表成绩单[政治]<9E+307)*(表成绩单[政治]>表成绩单[[#This Row],[政治]]))+1)} -> 45 | V15: {=IF(表成绩单[[#This Row],[历史]]="","",SUMPRODUCT((表成绩单[考试日期]=表成绩单[[#This Row],[考试日期]])*(表成绩单[历史]<9E+307)*(表成绩单[历史]>表成绩单[[#This Row],[历史]]))+1)} -> 18 | W15: {=IF(表成绩单[[#This Row],[总分]]="","",SUMPRODUCT((表成绩单[考试日期]=表成绩单[[#This Row],[考试日期]])*(表成绩单[总分]<9E+307)*(表成绩单[总分]>表成绩单[[#This Row],[总分]]))+1)} -> 10
D16: 45975 | E16: 19174450 | F16: 九年级17班 | G16: 凌子轩 | H16: 105 | I16: 116 | J16: 84.5 | K16: 87 | L16: 85 | M16: 90 | N16: 78 | O16: 645.5 | P16: {=IF(表成绩单[[#This Row],[语文]]="","",SUMPRODUCT((表成绩单[考试日期]=表成绩单[[#This Row],[考试日期]])*(表成绩单[语文]<9E+307)*(表成绩单[语文]>表成绩单[[#This Row],[语文]]))+1)} -> 80 | Q16: {=IF(表成绩单[[#This Row],[数学]]="","",SUMPRODUCT((表成绩单[考试日期]=表成绩单[[#This Row],[考试日期]])*(表成绩单[数学]<9E+307)*(表成绩单[数学]>表成绩单[[#This Row],[数学]]))+1)} -> 50 | R16: {=IF(表成绩单[[#This Row],[英语]]="","",SUMPRODUCT((表成绩单[考试日期]=表成绩单[[#This Row],[考试日期]])*(表成绩单[英语]<9E+307)*(表成绩单[英语]>表成绩单[[#This Row],[英语]]))+1)} -> 85 | S16: {=IF(表成绩单[[#This Row],[物理]]="","",SUMPRODUCT((表成绩单[考试日期]=表成绩单[[#This Row],[考试日期]])*(表成绩单[物理]<9E+307)*(表成绩单[物理]>表成绩单[[#This Row],[物理]]))+1)} -> 127 | T16: {=IF(表成绩单[[#This Row],[化学]]="","",SUMPRODUCT((表成绩单[考试日期]=表成绩单[[#This Row],[考试日期]])*(表成绩单[化学]<9E+307)*(表成绩单[化学]>表成绩单[[#This Row],[化学]]))+1)} -> 19 | U16: {=IF(表成绩单[[#This Row],[政治]]="","",SUMPRODUCT((表成绩单[考试日期]=表成绩单[[#This Row],[考试日期]])*(表成绩单[政治]<9E+307)*(表成绩单[政治]>表成绩单[[#This Row],[政治]]))+1)} -> 1 | V16: {=IF(表成绩单[[#This Row],[历史]]="","",SUMPRODUCT((表成绩单[考试日期]=表成绩单[[#This Row],[考试日期]])*(表成绩单[历史]<9E+307)*(表成绩单[历史]>表成绩单[[#This Row],[历史]]))+1)} -> 189 | W16: {=IF(表成绩单[[#This Row],[总分]]="","",SUMPRODUCT((表成绩单[考试日期]=表成绩单[[#This Row],[考试日期]])*(表成绩单[总分]<9E+307)*(表成绩单[总分]>表成绩单[[#This Row],[总分]]))+1)} -> 12
... D797: 45975 | E797: 19175593 | F797: 九年级2班 | G797: 范洛铨 | H797: 50 | I797: 28 | J797: 16.5 | K797: 18 | L797: 19 | M797: 30 | N797: 26 | O797: 187.5 | P797: {=IF(表成绩单[[#This Row],[语文]]="","",SUMPRODUCT((表成绩单[考试日期]=表成绩单[[#This Row],[考试日期]])*(表成绩单[语文]<9E+307)*(表成绩单[语文]>表成绩单[[#This Row],[语文]]))+1)} -> 792 | Q797: {=IF(表成绩单[[#This Row],[数学]]="","",SUMPRODUCT((表成绩单[考试日期]=表成绩单[[#This Row],[考试日期]])*(表成绩单[数学]<9E+307)*(表成绩单[数学]>表成绩单[[#This Row],[数学]]))+1)} -> 785 | R797: {=IF(表成绩单[[#This Row],[英语]]="","",SUMPRODUCT((表成绩单[考试日期]=表成绩单[[#This Row],[考试日期]])*(表成绩单[英语]<9E+307)*(表成绩单[英语]>表成绩单[[#This Row],[英语]]))+1)} -> 794 | S797: {=IF(表成绩单[[#This Row],[物理]]="","",SUMPRODUCT((表成绩单[考试日期]=表成绩单[[#This Row],[考试日期]])*(表成绩单[物理]<9E+307)*(表成绩单[物理]>表成绩单[[#This Row],[物理]]))+1)} -> 794 | T797: {=IF(表成绩单[[#This Row],[化学]]="","",SUMPRODUCT((表成绩单[考试日期]=表成绩单[[#This Row],[考试日期]])*(表成绩单[化学]<9E+307)*(表成绩单[化学]>表成绩单[[#This Row],[化学]]))+1)} -> 794 | U797: {=IF(表成绩单[[#This Row],[政治]]="","",SUMPRODUCT((表成绩单[考试日期]=表成绩单[[#This Row],[考试日期]])*(表成绩单[政治]<9E+307)*(表成绩单[政治]>表成绩单[[#This Row],[政治]]))+1)} -> 793 | V797: {=IF(表成绩单[[#This Row],[历史]]="","",SUMPRODUCT((表成绩单[考试日期]=表成绩单[[#This Row],[考试日期]])*(表成绩单[历史]<9E+307)*(表成绩单[历史]>表成绩单[[#This Row],[历史]]))+1)} -> 793 | W797: {=IF(表成绩单[[#This Row],[总分]]="","",SUMPRODUCT((表成绩单[考试日期]=表成绩单[[#This Row],[考试日期]])*(表成绩单[总分]<9E+307)*(表成绩单[总分]>表成绩单[[#This Row],[总分]]))+1)} -> 794
D798: 45975 | E798: 19172662 | F798: 九年级5班 | G798: 朱恒锋 | M798: 16 | O798: 16 | P798: {=IF(表成绩单[[#This Row],[语文]]="","",SUMPRODUCT((表成绩单[考试日期]=表成绩单[[#This Row],[考试日期]])*(表成绩单[语文]<9E+307)*(表成绩单[语文]>表成绩单[[#This Row],[语文]]))+1)} | Q798: {=IF(表成绩单[[#This Row],[数学]]="","",SUMPRODUCT((表成绩单[考试日期]=表成绩单[[#This Row],[考试日期]])*(表成绩单[数学]<9E+307)*(表成绩单[数学]>表成绩单[[#This Row],[数学]]))+1)} | R798: {=IF(表成绩单[[#This Row],[英语]]="","",SUMPRODUCT((表成绩单[考试日期]=表成绩单[[#This Row],[考试日期]])*(表成绩单[英语]<9E+307)*(表成绩单[英语]>表成绩单[[#This Row],[英语]]))+1)} | S798: {=IF(表成绩单[[#This Row],[物理]]="","",SUMPRODUCT((表成绩单[考试日期]=表成绩单[[#This Row],[考试日期]])*(表成绩单[物理]<9E+307)*(表成绩单[物理]>表成绩单[[#This Row],[物理]]))+1)} | T798: {=IF(表成绩单[[#This Row],[化学]]="","",SUMPRODUCT((表成绩单[考试日期]=表成绩单[[#This Row],[考试日期]])*(表成绩单[化学]<9E+307)*(表成绩单[化学]>表成绩单[[#This Row],[化学]]))+1)} | U798: {=IF(表成绩单[[#This Row],[政治]]="","",SUMPRODUCT((表成绩单[考试日期]=表成绩单[[#This Row],[考试日期]])*(表成绩单[政治]<9E+307)*(表成绩单[政治]>表成绩单[[#This Row],[政治]]))+1)} -> 794 | V798: {=IF(表成绩单[[#This Row],[历史]]="","",SUMPRODUCT((表成绩单[考试日期]=表成绩单[[#This Row],[考试日期]])*(表成绩单[历史]<9E+307)*(表成绩单[历史]>表成绩单[[#This Row],[历史]]))+1)} | W798: {=IF(表成绩单[[#This Row],[总分]]="","",SUMPRODUCT((表成绩单[考试日期]=表成绩单[[#This Row],[考试日期]])*(表成绩单[总分]<9E+307)*(表成绩单[总分]>表成绩单[[#This Row],[总分]]))+1)} -> 795
D799: 45975 | E799: 19173791 | F799: 九年级9班 | G799: 王威越 | P799: {=IF(表成绩单[[#This Row],[语文]]="","",SUMPRODUCT((表成绩单[考试日期]=表成绩单[[#This Row],[考试日期]])*(表成绩单[语文]<9E+307)*(表成绩单[语文]>表成绩单[[#This Row],[语文]]))+1)} | Q799: {=IF(表成绩单[[#This Row],[数学]]="","",SUMPRODUCT((表成绩单[考试日期]=表成绩单[[#This Row],[考试日期]])*(表成绩单[数学]<9E+307)*(表成绩单[数学]>表成绩单[[#This Row],[数学]]))+1)} | R799: {=IF(表成绩单[[#This Row],[英语]]="","",SUMPRODUCT((表成绩单[考试日期]=表成绩单[[#This Row],[考试日期]])*(表成绩单[英语]<9E+307)*(表成绩单[英语]>表成绩单[[#This Row],[英语]]))+1)} | S799: {=IF(表成绩单[[#This Row],[物理]]="","",SUMPRODUCT((表成绩单[考试日期]=表成绩单[[#This Row],[考试日期]])*(表成绩单[物理]<9E+307)*(表成绩单[物理]>表成绩单[[#This Row],[物理]]))+1)} | T799: {=IF(表成绩单[[#This Row],[化学]]="","",SUMPRODUCT((表成绩单[考试日期]=表成绩单[[#This Row],[考试日期]])*(表成绩单[化学]<9E+307)*(表成绩单[化学]>表成绩单[[#This Row],[化学]]))+1)} | U799: {=IF(表成绩单[[#This Row],[政治]]="","",SUMPRODUCT((表成绩单[考试日期]=表成绩单[[#This Row],[考试日期]])*(表成绩单[政治]<9E+307)*(表成绩单[政治]>表成绩单[[#This Row],[政治]]))+1)} | V799: {=IF(表成绩单[[#This Row],[历史]]="","",SUMPRODUCT((表成绩单[考试日期]=表成绩单[[#This Row],[考试日期]])*(表成绩单[历史]<9E+307)*(表成绩单[历史]>表成绩单[[#This Row],[历史]]))+1)} | W799: {=IF(表成绩单[[#This Row],[总分]]="","",SUMPRODUCT((表成绩单[考试日期]=表成绩单[[#This Row],[考试日期]])*(表成绩单[总分]<9E+307)*(表成绩单[总分]>表成绩单[[#This Row],[总分]]))+1)}
D800: 45975 | E800: 19174808 | F800: 九年级13班 | G800: 钟毓 | H800: 78 | I800: 90 | J800: 70 | K800: 82 | L800: 67 | O800: 387 | P800: {=IF(表成绩单[[#This Row],[语文]]="","",SUMPRODUCT((表成绩单[考试日期]=表成绩单[[#This Row],[考试日期]])*(表成绩单[语文]<9E+307)*(表成绩单[语文]>表成绩单[[#This Row],[语文]]))+1)} -> 728 | Q800: {=IF(表成绩单[[#This Row],[数学]]="","",SUMPRODUCT((表成绩单[考试日期]=表成绩单[[#This Row],[考试日期]])*(表成绩单[数学]<9E+307)*(表成绩单[数学]>表成绩单[[#This Row],[数学]]))+1)} -> 506 | R800: {=IF(表成绩单[[#This Row],[英语]]="","",SUMPRODUCT((表成绩单[考试日期]=表成绩单[[#This Row],[考试日期]])*(表成绩单[英语]<9E+307)*(表成绩单[英语]>表成绩单[[#This Row],[英语]]))+1)} -> 551 | S800: {=IF(表成绩单[[#This Row],[物理]]="","",SUMPRODUCT((表成绩单[考试日期]=表成绩单[[#This Row],[考试日期]])*(表成绩单[物理]<9E+307)*(表成绩单[物理]>表成绩单[[#This Row],[物理]]))+1)} -> 433 | T800: {=IF(表成绩单[[#This Row],[化学]]="","",SUMPRODUCT((表成绩单[考试日期]=表成绩单[[#This Row],[考试日期]])*(表成绩单[化学]<9E+307)*(表成绩单[化学]>表成绩单[[#This Row],[化学]]))+1)} -> 524 | U800: {=IF(表成绩单[[#This Row],[政治]]="","",SUMPRODUCT((表成绩单[考试日期]=表成绩单[[#This Row],[考试日期]])*(表成绩单[政治]<9E+307)*(表成绩单[政治]>表成绩单[[#This Row],[政治]]))+1)} | V800: {=IF(表成绩单[[#This Row],[历史]]="","",SUMPRODUCT((表成绩单[考试日期]=表成绩单[[#This Row],[考试日期]])*(表成绩单[历史]<9E+307)*(表成绩单[历史]>表成绩单[[#This Row],[历史]]))+1)} | W800: {=IF(表成绩单[[#This Row],[总分]]="","",SUMPRODUCT((表成绩单[考试日期]=表成绩单[[#This Row],[考试日期]])*(表成绩单[总分]<9E+307)*(表成绩单[总分]>表成绩单[[#This Row],[总分]]))+1)} -> 759
D801: 45975 | E801: 19175319 | F801: 九年级1班 | G801: 许耀丹 | P801: {=IF(表成绩单[[#This Row],[语文]]="","",SUMPRODUCT((表成绩单[考试日期]=表成绩单[[#This Row],[考试日期]])*(表成绩单[语文]<9E+307)*(表成绩单[语文]>表成绩单[[#This Row],[语文]]))+1)} | Q801: {=IF(表成绩单[[#This Row],[数学]]="","",SUMPRODUCT((表成绩单[考试日期]=表成绩单[[#This Row],[考试日期]])*(表成绩单[数学]<9E+307)*(表成绩单[数学]>表成绩单[[#This Row],[数学]]))+1)} | R801: {=IF(表成绩单[[#This Row],[英语]]="","",SUMPRODUCT((表成绩单[考试日期]=表成绩单[[#This Row],[考试日期]])*(表成绩单[英语]<9E+307)*(表成绩单[英语]>表成绩单[[#This Row],[英语]]))+1)} | S801: {=IF(表成绩单[[#This Row],[物理]]="","",SUMPRODUCT((表成绩单[考试日期]=表成绩单[[#This Row],[考试日期]])*(表成绩单[物理]<9E+307)*(表成绩单[物理]>表成绩单[[#This Row],[物理]]))+1)} | T801: {=IF(表成绩单[[#This Row],[化学]]="","",SUMPRODUCT((表成绩单[考试日期]=表成绩单[[#This Row],[考试日期]])*(表成绩单[化学]<9E+307)*(表成绩单[化学]>表成绩单[[#This Row],[化学]]))+1)} | U801: {=IF(表成绩单[[#This Row],[政治]]="","",SUMPRODUCT((表成绩单[考试日期]=表成绩单[[#This Row],[考试日期]])*(表成绩单[政治]<9E+307)*(表成绩单[政治]>表成绩单[[#This Row],[政治]]))+1)} | V801: {=IF(表成绩单[[#This Row],[历史]]="","",SUMPRODUCT((表成绩单[考试日期]=表成绩单[[#This Row],[考试日期]])*(表成绩单[历史]<9E+307)*(表成绩单[历史]>表成绩单[[#This Row],[历史]]))+1)} | W801: {=IF(表成绩单[[#This Row],[总分]]="","",SUMPRODUCT((表成绩单[考试日期]=表成绩单[[#This Row],[考试日期]])*(表成绩单[总分]<9E+307)*(表成绩单[总分]>表成绩单[[#This Row],[总分]]))+1)}
D802: 45975 | E802: 19175592 | F802: 九年级2班 | G802: 成紫强 | P802: {=IF(表成绩单[[#This Row],[语文]]="","",SUMPRODUCT((表成绩单[考试日期]=表成绩单[[#This Row],[考试日期]])*(表成绩单[语文]<9E+307)*(表成绩单[语文]>表成绩单[[#This Row],[语文]]))+1)} | Q802: {=IF(表成绩单[[#This Row],[数学]]="","",SUMPRODUCT((表成绩单[考试日期]=表成绩单[[#This Row],[考试日期]])*(表成绩单[数学]<9E+307)*(表成绩单[数学]>表成绩单[[#This Row],[数学]]))+1)} | R802: {=IF(表成绩单[[#This Row],[英语]]="","",SUMPRODUCT((表成绩单[考试日期]=表成绩单[[#This Row],[考试日期]])*(表成绩单[英语]<9E+307)*(表成绩单[英语]>表成绩单[[#This Row],[英语]]))+1)} | S802: {=IF(表成绩单[[#This Row],[物理]]="","",SUMPRODUCT((表成绩单[考试日期]=表成绩单[[#This Row],[考试日期]])*(表成绩单[物理]<9E+307)*(表成绩单[物理]>表成绩单[[#This Row],[物理]]))+1)} | T802: {=IF(表成绩单[[#This Row],[化学]]="","",SUMPRODUCT((表成绩单[考试日期]=表成绩单[[#This Row],[考试日期]])*(表成绩单[化学]<9E+307)*(表成绩单[化学]>表成绩单[[#This Row],[化学]]))+1)} | U802: {=IF(表成绩单[[#This Row],[政治]]="","",SUMPRODUCT((表成绩单[考试日期]=表成绩单[[#This Row],[考试日期]])*(表成绩单[政治]<9E+307)*(表成绩单[政治]>表成绩单[[#This Row],[政治]]))+1)} | V802: {=IF(表成绩单[[#This Row],[历史]]="","",SUMPRODUCT((表成绩单[考试日期]=表成绩单[[#This Row],[考试日期]])*(表成绩单[历史]<9E+307)*(表成绩单[历史]>表成绩单[[#This Row],[历史]]))+1)} | W802: {=IF(表成绩单[[#This Row],[总分]]="","",SUMPRODUCT((表成绩单[考试日期]=表成绩单[[#This Row],[考试日期]])*(表成绩单[总分]<9E+307)*(表成绩单[总分]>表成绩单[[#This Row],[总分]]))+1)}
D803: 45975 | E803: 19175619 | F803: 九年级2班 | G803: 闫浩誉 | P803: {=IF(表成绩单[[#This Row],[语文]]="","",SUMPRODUCT((表成绩单[考试日期]=表成绩单[[#This Row],[考试日期]])*(表成绩单[语文]<9E+307)*(表成绩单[语文]>表成绩单[[#This Row],[语文]]))+1)} | Q803: {=IF(表成绩单[[#This Row],[数学]]="","",SUMPRODUCT((表成绩单[考试日期]=表成绩单[[#This Row],[考试日期]])*(表成绩单[数学]<9E+307)*(表成绩单[数学]>表成绩单[[#This Row],[数学]]))+1)} | R803: {=IF(表成绩单[[#This Row],[英语]]="","",SUMPRODUCT((表成绩单[考试日期]=表成绩单[[#This Row],[考试日期]])*(表成绩单[英语]<9E+307)*(表成绩单[英语]>表成绩单[[#This Row],[英语]]))+1)} | S803: {=IF(表成绩单[[#This Row],[物理]]="","",SUMPRODUCT((表成绩单[考试日期]=表成绩单[[#This Row],[考试日期]])*(表成绩单[物理]<9E+307)*(表成绩单[物理]>表成绩单[[#This Row],[物理]]))+1)} | T803: {=IF(表成绩单[[#This Row],[化学]]="","",SUMPRODUCT((表成绩单[考试日期]=表成绩单[[#This Row],[考试日期]])*(表成绩单[化学]<9E+307)*(表成绩单[化学]>表成绩单[[#This Row],[化学]]))+1)} | U803: {=IF(表成绩单[[#This Row],[政治]]="","",SUMPRODUCT((表成绩单[考试日期]=表成绩单[[#This Row],[考试日期]])*(表成绩单[政治]<9E+307)*(表成绩单[政治]>表成绩单[[#This Row],[政治]]))+1)} | V803: {=IF(表成绩单[[#This Row],[历史]]="","",SUMPRODUCT((表成绩单[考试日期]=表成绩单[[#This Row],[考试日期]])*(表成绩单[历史]<9E+307)*(表成绩单[历史]>表成绩单[[#This Row],[历史]]))+1)} | W803: {=IF(表成绩单[[#This Row],[总分]]="","",SUMPRODUCT((表成绩单[考试日期]=表成绩单[[#This Row],[考试日期]])*(表成绩单[总分]<9E+307)*(表成绩单[总分]>表成绩单[[#This Row],[总分]]))+1)}
D804: 45975 | E804: 19175624 | F804: 九年级2班 | G804: 张馨予 | P804: {=IF(表成绩单[[#This Row],[语文]]="","",SUMPRODUCT((表成绩单[考试日期]=表成绩单[[#This Row],[考试日期]])*(表成绩单[语文]<9E+307)*(表成绩单[语文]>表成绩单[[#This Row],[语文]]))+1)} | Q804: {=IF(表成绩单[[#This Row],[数学]]="","",SUMPRODUCT((表成绩单[考试日期]=表成绩单[[#This Row],[考试日期]])*(表成绩单[数学]<9E+307)*(表成绩单[数学]>表成绩单[[#This Row],[数学]]))+1)} | R804: {=IF(表成绩单[[#This Row],[英语]]="","",SUMPRODUCT((表成绩单[考试日期]=表成绩单[[#This Row],[考试日期]])*(表成绩单[英语]<9E+307)*(表成绩单[英语]>表成绩单[[#This Row],[英语]]))+1)} | S804: {=IF(表成绩单[[#This Row],[物理]]="","",SUMPRODUCT((表成绩单[考试日期]=表成绩单[[#This Row],[考试日期]])*(表成绩单[物理]<9E+307)*(表成绩单[物理]>表成绩单[[#This Row],[物理]]))+1)} | T804: {=IF(表成绩单[[#This Row],[化学]]="","",SUMPRODUCT((表成绩单[考试日期]=表成绩单[[#This Row],[考试日期]])*(表成绩单[化学]<9E+307)*(表成绩单[化学]>表成绩单[[#This Row],[化学]]))+1)} | U804: {=IF(表成绩单[[#This Row],[政治]]="","",SUMPRODUCT((表成绩单[考试日期]=表成绩单[[#This Row],[考试日期]])*(表成绩单[政治]<9E+307)*(表成绩单[政治]>表成绩单[[#This Row],[政治]]))+1)} | V804: {=IF(表成绩单[[#This Row],[历史]]="","",SUMPRODUCT((表成绩单[考试日期]=表成绩单[[#This Row],[考试日期]])*(表成绩单[历史]<9E+307)*(表成绩单[历史]>表成绩单[[#This Row],[历史]]))+1)} | W804: {=IF(表成绩单[[#This Row],[总分]]="","",SUMPRODUCT((表成绩单[考试日期]=表成绩单[[#This Row],[考试日期]])*(表成绩单[总分]<9E+307)*(表成绩单[总分]>表成绩单[[#This Row],[总分]]))+1)}
D805: 45975 | E805: 19177598 | F805: 九年级3班 | G805: 何致远 | P805: {=IF(表成绩单[[#This Row],[语文]]="","",SUMPRODUCT((表成绩单[考试日期]=表成绩单[[#This Row],[考试日期]])*(表成绩单[语文]<9E+307)*(表成绩单[语文]>表成绩单[[#This Row],[语文]]))+1)} | Q805: {=IF(表成绩单[[#This Row],[数学]]="","",SUMPRODUCT((表成绩单[考试日期]=表成绩单[[#This Row],[考试日期]])*(表成绩单[数学]<9E+307)*(表成绩单[数学]>表成绩单[[#This Row],[数学]]))+1)} | R805: {=IF(表成绩单[[#This Row],[英语]]="","",SUMPRODUCT((表成绩单[考试日期]=表成绩单[[#This Row],[考试日期]])*(表成绩单[英语]<9E+307)*(表成绩单[英语]>表成绩单[[#This Row],[英语]]))+1)} | S805: {=IF(表成绩单[[#This Row],[物理]]="","",SUMPRODUCT((表成绩单[考试日期]=表成绩单[[#This Row],[考试日期]])*(表成绩单[物理]<9E+307)*(表成绩单[物理]>表成绩单[[#This Row],[物理]]))+1)} | T805: {=IF(表成绩单[[#This Row],[化学]]="","",SUMPRODUCT((表成绩单[考试日期]=表成绩单[[#This Row],[考试日期]])*(表成绩单[化学]<9E+307)*(表成绩单[化学]>表成绩单[[#This Row],[化学]]))+1)} | U805: {=IF(表成绩单[[#This Row],[政治]]="","",SUMPRODUCT((表成绩单[考试日期]=表成绩单[[#This Row],[考试日期]])*(表成绩单[政治]<9E+307)*(表成绩单[政治]>表成绩单[[#This Row],[政治]]))+1)} | V805: {=IF(表成绩单[[#This Row],[历史]]="","",SUMPRODUCT((表成绩单[考试日期]=表成绩单[[#This Row],[考试日期]])*(表成绩单[历史]<9E+307)*(表成绩单[历史]>表成绩单[[#This Row],[历史]]))+1)} | W805: {=IF(表成绩单[[#This Row],[总分]]="","",SUMPRODUCT((表成绩单[考试日期]=表成绩单[[#This Row],[考试日期]])*(表成绩单[总分]<9E+307)*(表成绩单[总分]>表成绩单[[#This Row],[总分]]))+1)}
